<?xml version="1.0"?>
<robot name="box_bot">

  <material name="red">
      <color rgba="1.0 0.0 0.0 1"/>
  </material>

  <material name="green_light">
      <color rgba="0.0 1.0 0.0 1"/>
  </material>

  <material name="green_dark">
    <color rgba="0.0 0.5 0.0 1"/>
  </material>

  <material name="blue">
      <color rgba="0.0 0.0 1.0 1"/>
  </material>

  <material name="black">
      <color rgba="0.0 0.0 0.0 1"/>
  </material>

  <material name="white">
      <color rgba="1.0 1.0 1.0 1"/>
  </material>

  <link name="base_link">
  </link>


  <!-- Body -->
  <link name="chassis">
    <visual>
      <geometry>
        <mesh filename="package://my_box_bot_description/meshes/cute_cube.dae" scale="0.1 0.1 0.1"/>
      </geometry>
    </visual>
  </link>

  <joint name="base_link_joint" type="fixed">
    <origin rpy="0 0 0" xyz="0 0 0" />
    <parent link="base_link" />
    <child link="chassis" />
  </joint>

  <!-- Wheel Left -->
  <link name="left_wheel">      
      <visual>
        <origin rpy="0 1.5707 1.5707" xyz="0 0 0"/>
        <geometry>
          <cylinder length="0.001" radius="0.035"/>
        </geometry>
        <material name="black"/>
      </visual>
  </link>


  <joint name="joint_left_wheel" type="continuous">
    <origin rpy="0 0 0" xyz="0 0.05 -0.025"/>
    <child link="left_wheel"/>
    <parent link="chassis"/>
    <axis rpy="0 0 0" xyz="0 1 0"/>
    <limit effort="10000" velocity="1000"/>
    <joint_properties damping="1.0" friction="1.0"/>
  </joint>

  <!-- Wheel Right -->
  <link name="right_wheel">      
      <visual>
        <origin rpy="0 1.5707 1.5707" xyz="0 0 0"/>
        <geometry>
          <cylinder length="0.001" radius="0.035"/>
        </geometry>
        <material name="white"/>
      </visual>
  </link>


  <joint name="joint_right_wheel" type="continuous">  
    <origin rpy="0 0 0" xyz="0 -0.05 -0.025"/>
    <child link="right_wheel"/>
    <parent link="chassis"/>
    <axis rpy="0 0 0" xyz="0 1 0"/>
    <limit effort="10000" velocity="1000"/>
    <joint_properties damping="1.0" friction="1.0"/>
  </joint>


  <!-- Caster Wheel Front -->
  <link name="front_yaw_link">
      <visual>
        <origin rpy="0 1.5707 1.5707" xyz="0 0 0"/>
        <geometry>          
          <cylinder length="0.001" radius="0.0045000000000000005"/>
        </geometry>
        <material name="blue"/>
      </visual>
  </link>

  <joint name="front_yaw_joint" type="continuous">
    <origin rpy="0 0 0" xyz="0.04 0 -0.05" />
    <parent link="chassis" />
    <child link="front_yaw_link" />
    <axis xyz="0 0 1" />
    <limit effort="1000.0" velocity="100.0" />
    <dynamics damping="0.0" friction="0.1"/>
  </joint>



  <link name="front_roll_link">
      <visual>
        <origin rpy="0 1.5707 1.5707" xyz="0 0 0"/>
        <geometry>
          <cylinder length="0.001" radius="0.0045000000000000005"/>
        </geometry>
        <material name="red"/>
      </visual>
  </link>

  <joint name="front_roll_joint" type="continuous">
    <origin rpy="0 0 0" xyz="0 0 0" />
    <parent link="front_yaw_link" />
    <child link="front_roll_link" />
    <axis xyz="1 0 0" />
    <limit effort="1000.0" velocity="100.0" />
    <dynamics damping="0.0" friction="0.1"/>
  </joint>


  <link name="front_pitch_link">
    <visual>
      <origin rpy="0 1.5707 1.5707" xyz="0 0 0"/>
      <geometry>
        <sphere radius="0.010"/>
      </geometry>
      <material name="green_dark"/>
    </visual>
  </link>



  <joint name="front_pitch_joint" type="continuous">
    <origin rpy="0 0 0" xyz="0 0 0" />
    <parent link="front_roll_link" />
    <child link="front_pitch_link" />
    <axis xyz="0 1 0" />
    <limit effort="1000.0" velocity="100.0" />
    <dynamics damping="0.0" friction="0.1"/>
  </joint>

<!-- Caster Wheel Back -->
  <link name="back_yaw_link">
    <visual>
        <origin rpy="0 1.5707 1.5707" xyz="0 0 0"/>
        <geometry>
          <cylinder length="0.001" radius="0.0045000000000000005"/>
        </geometry>
        <material name="blue"/>
      </visual>

  </link>

  <joint name="back_yaw_joint" type="continuous">
    <origin rpy="0 0 0" xyz="-0.04 0 -0.05" />
    <parent link="chassis" />
    <child link="back_yaw_link" />
    <axis xyz="0 0 1" />
    <limit effort="1000.0" velocity="100.0" />
    <dynamics damping="0.0" friction="0.1"/>
  </joint>



  <link name="back_roll_link">
      <visual>
        <origin rpy="0 1.5707 1.5707" xyz="0 0 0"/>
        <geometry>
          <cylinder length="0.001" radius="0.0045000000000000005"/>
        </geometry>
        <material name="red"/>
      </visual>
  </link>

  <joint name="back_roll_joint" type="continuous">
    <origin rpy="0 0 0" xyz="0 0 0" />
    <parent link="back_yaw_link" />
    <child link="back_roll_link" />
    <axis xyz="1 0 0" />
    <limit effort="1000.0" velocity="100.0" />
    <dynamics damping="0.0" friction="0.1"/>
  </joint>



  <link name="back_pitch_link">
    <visual>
      <origin rpy="0 1.5707 1.5707" xyz="0 0 0"/>
      <geometry>
        <sphere radius="0.010"/>
      </geometry>
      <material name="green_light"/>
    </visual>
  </link>

  <joint name="back_pitch_joint" type="continuous">
    <origin rpy="0 0 0" xyz="0 0 0" />
    <parent link="back_roll_link" />
    <child link="back_pitch_link" />
    <axis xyz="0 1 0" />
    <limit effort="1000.0" velocity="100.0" />
    <dynamics damping="0.0" friction="0.1"/>
  </joint>

</robot>