<sdf version='1.7'>
  <model name='omni_robot'>

    <link name='base_link'>
      <inertial>
        <pose>0 0 0 0 0 0</pose>
        <mass>1.167</mass>
        <inertia>
          <ixx>0.0016</ixx>
          <ixy>0</ixy>
          <ixz>0</ixz>
          <iyy>0.0016</iyy>
          <iyz>0</iyz>
          <izz>0.0032</izz>
        </inertia>
      </inertial>
      <collision name='base_footprint_fixed_joint_lump__base_link_collision'>
        <pose>0 0 0 0 0 0</pose>
        <geometry>
          <mesh>
            <scale>1 1 1</scale>
            <uri>model://rs_robot/meshes/STL/base/base_link.stl</uri>
          </mesh>
        </geometry>
        <surface>
          <contact>
            <ode/>
          </contact>
          <friction>
            <ode>
              <mu>0.05</mu>
              <mu2>0.05</mu2>
            </ode>
          </friction>
        </surface>
      </collision>

<collision name='base_footprint_fixed_joint_lump__camera_link_collision_1'>
        <pose>0.094717 0 0.138329 0 -0.436332 0</pose>
        <geometry>
          <box>
            <size>0.02505 0.09 0.025</size>
          </box>
        </geometry>
        <surface>
          <contact>
            <ode>
              <kp>1e+13</kp>
              <kd>1</kd>
            </ode>
          </contact>
          <friction>
            <ode>
              <mu2>1</mu2>
              <fdir1>0 0 0</fdir1>
            </ode>
          </friction>
        </surface>
      </collision>
      <collision name='base_footprint_fixed_joint_lump__front_camera_link_collision_2'>
        <pose>0.12 0 0.115 0 -0 0</pose>
        <geometry>
          <mesh>
            <scale>1 1 1</scale>
            <uri>model://rs_robot/meshes/STL/camera/camera.stl</uri>
          </mesh>
        </geometry>
        <surface>
          <contact>
            <ode/>
          </contact>
          <friction>
            <ode/>
          </friction>
        </surface>
      </collision>
      <collision name='base_footprint_fixed_joint_lump__left_camera_link_collision_3'>
        <pose>0 0.12 0.115 0 0 1.5708</pose>
        <geometry>
          <mesh>
            <scale>1 1 1</scale>
            <uri>model://rs_robot/meshes/STL/camera/camera.stl</uri>
          </mesh>
        </geometry>
        <surface>
          <contact>
            <ode/>
          </contact>
          <friction>
            <ode/>
          </friction>
        </surface>
      </collision>
      <collision name='base_footprint_fixed_joint_lump__right_camera_link_collision_4'>
        <pose>0 -0.12 0.115 0 0 -1.5708</pose>
        <geometry>
          <mesh>
            <scale>1 1 1</scale>
            <uri>model://rs_robot/meshes/STL/camera/camera.stl</uri>
          </mesh>
        </geometry>
        <surface>
          <contact>
            <ode/>
          </contact>
          <friction>
            <ode/>
          </friction>
        </surface>
      </collision>
      <collision name='base_footprint_fixed_joint_lump__back_camera_link_collision_2'>
        <pose>-0.12 0 0.115 0 0 3.1416</pose>
        <geometry>
          <mesh>
            <scale>1 1 1</scale>
            <uri>model://rs_robot/meshes/STL/camera/camera.stl</uri>
          </mesh>
        </geometry>
        <surface>
          <contact>
            <ode/>
          </contact>
          <friction>
            <ode/>
          </friction>
        </surface>
      </collision>

      <visual name='base_footprint_fixed_joint_lump__base_link_visual'>
        <pose>0 0 0 0 0 0</pose>
        <geometry>
          <mesh>
            <scale>1 1 1</scale>
            <uri>model://rs_robot/meshes/DAE/base/base_link.dae</uri>
          </mesh>
        </geometry>
      </visual>

      <visual name='base_footprint_fixed_joint_lump__camera_link_visual_1'>
        <pose>0.108221 0 0.144626 1.13446 -0 1.5708</pose>
        <geometry>
          <mesh>
            <scale>1 1 1</scale>
            <uri>model://realsense2_description/meshes/d435.dae</uri>
          </mesh>
        </geometry>
      </visual>
      <visual name='base_footprint_fixed_joint_lump__front_camera_link_visual_2'>
        <pose>0.12 0 0.115 0 -0 0</pose>
        <geometry>
          <mesh>
            <scale>1 1 1</scale>
            <uri>model://rs_robot/meshes/DAE/camera/camera.dae</uri>
          </mesh>
        </geometry>
      </visual>

      <visual name='base_footprint_fixed_joint_lump__left_camera_link_visual_4'>
        <pose>0 0.12 0.115 0 0 1.5708</pose>
        <geometry>
          <mesh>
            <scale>1 1 1</scale>
            <uri>model://rs_robot/meshes/DAE/camera/camera.dae</uri>
          </mesh>
        </geometry>
      </visual>
      <visual name='base_footprint_fixed_joint_lump__right_camera_link_visual_5'>
        <pose>0 -0.12 0.115 0 0 -1.5708</pose>
        <geometry>
          <mesh>
            <scale>1 1 1</scale>
            <uri>model://rs_robot/meshes/DAE/camera/camera.dae</uri>
          </mesh>
        </geometry>
      </visual>
      <visual name='base_footprint_fixed_joint_lump__back_camera_link_visual_6'>
        <pose>-0.12 0 0.115 0 0 3.1416</pose>
        <geometry>
          <mesh>
            <scale>1 1 1</scale>
            <uri>model://rs_robot/meshes/DAE/camera/camera.dae</uri>
          </mesh>
        </geometry>
      </visual>

      <self_collide>0</self_collide>

      <sensor name='front' type="wideanglecamera">
        <update_rate>10</update_rate>
        <camera name='front_camera'>
          <pose>0 0 0 0 0 0</pose>
          <horizontal_fov>3.1415</horizontal_fov>
          <image>
            <width>640</width>
            <height>480</height>
            <format>R8G8B8</format>
          </image>
          <clip>
            <near>0.1</near>
            <far>100</far>
          </clip>
          <lens>
            <type>custom</type>
            <scale_to_hfov>true</scale_to_hfov>
            <cutoff_angle>3.1415</cutoff_angle>
            <env_texture_size>512</env_texture_size>
              <custom_function>
                <c1>1.05</c1>
                <c2>4</c2>
                <f>1.0</f>
                <fun>tan</fun>
             </custom_function>
          </lens>
          <noise>
            <type>gaussian</type>
            <mean>0</mean>
            <stddev>0.007</stddev>
          </noise>
        </camera>
        <plugin name='camera_controller_front' filename='libgazebo_ros_camera.so'>
          <alwaysOn>1</alwaysOn>
          <updateRate>0.0</updateRate>
          <cameraName>front_camera</cameraName>
          <imageTopicName>image_raw</imageTopicName>
          <cameraInfoTopicName>camera_info</cameraInfoTopicName>
          <frameName>front_link</frameName>
          <hackBaseline>0.0</hackBaseline>
          <distortionK1>0.0</distortionK1>
          <distortionK2>0.0</distortionK2>
          <distortionK3>0.0</distortionK3>
          <distortionT1>0.0</distortionT1>
          <distortionT2>0.0</distortionT2>
        </plugin>
        <pose>0.12 0 0.115 0 -0 0</pose>
      </sensor>
      <sensor name='left' type="wideanglecamera">
        <update_rate>10</update_rate>
        <camera name='left_camera'>
          <pose>0 0 0 0 0 0</pose>
          <horizontal_fov>3.1415</horizontal_fov>
          <image>
            <width>640</width>
            <height>480</height>
            <format>R8G8B8</format>
          </image>
          <clip>
            <near>0.1</near>
            <far>100</far>
          </clip>
          <lens>
            <type>custom</type>
            <scale_to_hfov>true</scale_to_hfov>
            <cutoff_angle>3.1415</cutoff_angle>
            <env_texture_size>512</env_texture_size>
              <custom_function>
                <c1>1.05</c1>
                <c2>4</c2>
                <f>1.0</f>
                <fun>tan</fun>
             </custom_function>
          </lens>
          <noise>
            <type>gaussian</type>
            <mean>0</mean>
            <stddev>0.007</stddev>
          </noise>
        </camera>
        <plugin name='camera_controller_left' filename='libgazebo_ros_camera.so'>
          <alwaysOn>1</alwaysOn>
          <updateRate>0.0</updateRate>
          <cameraName>left_camera</cameraName>
          <imageTopicName>image_raw</imageTopicName>
          <cameraInfoTopicName>camera_info</cameraInfoTopicName>
          <frameName>left_link</frameName>
          <hackBaseline>0.0</hackBaseline>
          <distortionK1>0.0</distortionK1>
          <distortionK2>0.0</distortionK2>
          <distortionK3>0.0</distortionK3>
          <distortionT1>0.0</distortionT1>
          <distortionT2>0.0</distortionT2>
        </plugin>
        <pose>0 0.12 0.115 0 0 1.5708</pose>
      </sensor>
      <sensor name='right' type="wideanglecamera">
        <update_rate>10</update_rate>
        <camera name='right_camera'>
          <pose>0 0 0 0 -0 0</pose>
          <horizontal_fov>3.1415</horizontal_fov>
          <image>
            <width>640</width>
            <height>480</height>
            <format>R8G8B8</format>
          </image>
          <clip>
            <near>0.1</near>
            <far>100</far>
          </clip>
          <lens>
            <type>custom</type>
            <scale_to_hfov>true</scale_to_hfov>
            <cutoff_angle>3.1415</cutoff_angle>
            <env_texture_size>512</env_texture_size>
              <custom_function>
                <c1>1.05</c1>
                <c2>4</c2>
                <f>1.0</f>
                <fun>tan</fun>
             </custom_function>
          </lens>
          <noise>
            <type>gaussian</type>
            <mean>0</mean>
            <stddev>0.007</stddev>
          </noise>
        </camera>
        <plugin name='camera_controller_right' filename='libgazebo_ros_camera.so'>
          <alwaysOn>1</alwaysOn>
          <updateRate>0.0</updateRate>
          <cameraName>right_camera</cameraName>
          <imageTopicName>image_raw</imageTopicName>
          <cameraInfoTopicName>camera_info</cameraInfoTopicName>
          <frameName>right_link</frameName>
          <hackBaseline>0.0</hackBaseline>
          <distortionK1>0.0</distortionK1>
          <distortionK2>0.0</distortionK2>
          <distortionK3>0.0</distortionK3>
          <distortionT1>0.0</distortionT1>
          <distortionT2>0.0</distortionT2>
        </plugin>
        <pose>0 -0.12 0.115 0 0 -1.5708</pose>
      </sensor>        
      <sensor name='back' type="wideanglecamera">
        <update_rate>10</update_rate>
        <camera name='back_camera'>
          <pose>0 0 0 0 0 0</pose>
          <horizontal_fov>3.1415</horizontal_fov>
          <image>
            <width>640</width>
            <height>480</height>
            <format>R8G8B8</format>
          </image>
          <clip>
            <near>0.1</near>
            <far>100</far>
          </clip>
          <lens>
            <type>custom</type>
            <scale_to_hfov>true</scale_to_hfov>
            <cutoff_angle>3.1415</cutoff_angle>
            <env_texture_size>512</env_texture_size>
              <custom_function>
                <c1>1.05</c1>
                <c2>4</c2>
                <f>1.0</f>
                <fun>tan</fun>
             </custom_function>
          </lens>
          <noise>
            <type>gaussian</type>
            <mean>0</mean>
            <stddev>0.007</stddev>
          </noise>
        </camera>
        <plugin name='camera_controller_back' filename='libgazebo_ros_camera.so'>
          <alwaysOn>1</alwaysOn>
          <updateRate>0.0</updateRate>
          <cameraName>back_camera</cameraName>
          <imageTopicName>image_raw</imageTopicName>
          <cameraInfoTopicName>camera_info</cameraInfoTopicName>
          <frameName>back_link</frameName>
          <hackBaseline>0.0</hackBaseline>
          <distortionK1>0.0</distortionK1>
          <distortionK2>0.0</distortionK2>
          <distortionK3>0.0</distortionK3>
          <distortionT1>0.0</distortionT1>
          <distortionT2>0.0</distortionT2>
        </plugin>
        <pose>-0.12 0 0.115 0 0 3.1416</pose>
      </sensor>

    </link>
    <joint name='first_wheel_joint' type='revolute'>
      <pose relative_to='base_link'>0.086338 -0.086338 -0.022 0 0 -2.3562</pose>
      <parent>base_link</parent>
      <child>first_wheel_link</child>
      <axis>
        <xyz>0 1 0</xyz>
        <limit>
          <effort>100</effort>
          <velocity>100</velocity>
          <lower>-1e+16</lower>
          <upper>1e+16</upper>
        </limit>
        <dynamics>
          <spring_reference>0</spring_reference>
          <spring_stiffness>0</spring_stiffness>
        </dynamics>
      </axis>
    </joint>
    <link name='first_wheel_link'>
      <pose relative_to='first_wheel_joint'>0 0 0 0 -0 0</pose>
      <inertial>
        <pose>0 -0.011 0 0 -0 0</pose>
        <mass>0.25</mass>
        <inertia>
          <ixx>0.00031</ixx>
          <ixy>0</ixy>
          <ixz>0</ixz>
          <iyy>0.0005</iyy>
          <iyz>0</iyz>
          <izz>0.00031</izz>
        </inertia>
      </inertial>
      <collision name='first_wheel_link_collision'>
        <pose>0 0 0 0 -0 0</pose>
        <geometry>
          <mesh>
            <scale>1 1 1</scale>
            <uri>model://rs_robot/meshes/STL/omni_wheel/omni_wheel.stl</uri>
          </mesh>
        </geometry>
        <surface>
          <contact>
            <ode>
              <max_vel>0.01</max_vel>
            </ode>
          </contact>
          <friction>
            <ode>
              <mu>1.5</mu>
              <mu2>1.5</mu2>
              <kp>1e15</kp>
              <kd>1e13</kd>
            </ode>
          </friction>
          <bounce>
            <restitution_coefficient>0.01</restitution_coefficient>
            <threshold>0</threshold>
          </bounce>
        </surface>
      </collision>
      <visual name='first_wheel_link_visual'>
        <pose>0 0 0 0 -0 0</pose>
        <geometry>
          <mesh>
            <scale>1 1 1</scale>
            <uri>model://rs_robot/meshes/DAE/omni_wheel/omni_wheel.dae</uri>
          </mesh>
        </geometry>
      </visual>
      <self_collide>0</self_collide>
    </link>
    <joint name='r10_F_roller_joint' type='revolute'>
      <pose relative_to='first_wheel_link'>-0.022885 0.006 -0.007436 1.25664 -0 1.5708</pose>
      <parent>first_wheel_link</parent>
      <child>r10_F_roller_link</child>
      <axis>
        <xyz>0 1 0</xyz>
        <limit>
          <lower>-1e+16</lower>
          <upper>1e+16</upper>
        </limit>
        <dynamics>
          <spring_reference>0</spring_reference>
          <spring_stiffness>0</spring_stiffness>
        </dynamics>
      </axis>
    </joint>
    <link name='r10_F_roller_link'>
      <pose relative_to='r10_F_roller_joint'>0 0 0 0 -0 0</pose>
      <inertial>
        <pose>0 0 0 0 -0 0</pose>
        <mass>0.009</mass>
        <inertia>
          <ixx>1.257e-06</ixx>
          <ixy>0</ixy>
          <ixz>0</ixz>
          <iyy>3.42e-07</iyy>
          <iyz>0</iyz>
          <izz>1.257e-06</izz>
        </inertia>
      </inertial>
      <collision name='r10_F_roller_link_collision'>
        <pose>0 0 0 0 0 0</pose>
        <geometry>
          <mesh>
            <scale>1 1 1</scale>
            <uri>model://rs_robot/meshes/STL/roller/roller.stl</uri>
          </mesh>
        </geometry>
        <surface>
          <contact>
            <ode>
              <max_vel>0.01</max_vel>
            </ode>
          </contact>
          <friction>
            <ode>
              <mu>1.5</mu>
              <mu2>1.5</mu2>
              <kp>1e15</kp>
              <kd>1e13</kd>
            </ode>
          </friction>
          <bounce>
            <restitution_coefficient>0.01</restitution_coefficient>
            <threshold>0</threshold>
          </bounce>
        </surface>
      </collision>
      <visual name='r10_F_roller_link_visual'>
        <pose>0 0 0 0 -0 0</pose>
        <geometry>
          <mesh>
            <scale>1 1 1</scale>
            <uri>model://rs_robot/meshes/DAE/roller/roller.dae</uri>
          </mesh>
        </geometry>
      </visual>
    </link>
    <joint name='r1_F_roller_joint' type='revolute'>
      <pose relative_to='first_wheel_link'>0 -0.006 0.024063 0 -0 1.5708</pose>
      <parent>first_wheel_link</parent>
      <child>r1_F_roller_link</child>
      <axis>
        <xyz>0 1 0</xyz>
        <limit>
          <lower>-1e+16</lower>
          <upper>1e+16</upper>
        </limit>
        <dynamics>
          <spring_reference>0</spring_reference>
          <spring_stiffness>0</spring_stiffness>
        </dynamics>
      </axis>
    </joint>
    <link name='r1_F_roller_link'>
      <pose relative_to='r1_F_roller_joint'>0 0 0 0 -0 0</pose>
      <inertial>
        <pose>0 0 0 0 -0 0</pose>
        <mass>0.009</mass>
        <inertia>
          <ixx>1.257e-06</ixx>
          <ixy>0</ixy>
          <ixz>0</ixz>
          <iyy>3.42e-07</iyy>
          <iyz>0</iyz>
          <izz>1.257e-06</izz>
        </inertia>
      </inertial>
      <collision name='r1_F_roller_link_collision'>
        <pose>0 0 0 0 -0 0</pose>
        <geometry>
          <mesh>
            <scale>1 1 1</scale>
            <uri>model://rs_robot/meshes/STL/roller/roller.stl</uri>
          </mesh>
        </geometry>
        <surface>
          <contact>
            <ode>
              <max_vel>0.01</max_vel>
            </ode>
          </contact>
          <friction>
            <ode>
              <mu>1.5</mu>
              <mu2>1.5</mu2>
              <kp>1e15</kp>
              <kd>1e13</kd>
            </ode>
          </friction>
          <bounce>
            <restitution_coefficient>0.01</restitution_coefficient>
            <threshold>0</threshold>
          </bounce>
        </surface>
      </collision>
      <visual name='r1_F_roller_link_visual'>
        <pose>0 0 0 0 -0 0</pose>
        <geometry>
          <mesh>
            <scale>1 1 1</scale>
            <uri>model://rs_robot/meshes/DAE/roller/roller.dae</uri>
          </mesh>
        </geometry>
      </visual>
    </link>
    <joint name='r2_F_roller_joint' type='revolute'>
      <pose relative_to='first_wheel_link'>-0.022885 -0.006 0.007436 -1.25664 -0 1.5708</pose>
      <parent>first_wheel_link</parent>
      <child>r2_F_roller_link</child>
      <axis>
        <xyz>0 1 0</xyz>
        <limit>
          <lower>-1e+16</lower>
          <upper>1e+16</upper>
        </limit>
        <dynamics>
          <spring_reference>0</spring_reference>
          <spring_stiffness>0</spring_stiffness>
        </dynamics>
      </axis>
    </joint>
    <link name='r2_F_roller_link'>
      <pose relative_to='r2_F_roller_joint'>0 0 0 0 -0 0</pose>
      <inertial>
        <pose>0 0 0 0 -0 0</pose>
        <mass>0.009</mass>
        <inertia>
          <ixx>1.257e-06</ixx>
          <ixy>0</ixy>
          <ixz>0</ixz>
          <iyy>3.42e-07</iyy>
          <iyz>0</iyz>
          <izz>1.257e-06</izz>
        </inertia>
      </inertial>
      <collision name='r2_F_roller_link_collision'>
        <pose>0 0 0 0 -0 0</pose>
        <geometry>
          <mesh>
            <scale>1 1 1</scale>
            <uri>model://rs_robot/meshes/STL/roller/roller.stl</uri>
          </mesh>
        </geometry>
        <surface>
          <contact>
            <ode>
              <max_vel>0.01</max_vel>
            </ode>
          </contact>
          <friction>
            <ode>
              <mu>1.5</mu>
              <mu2>1.5</mu2>
              <kp>1e15</kp>
              <kd>1e13</kd>
            </ode>
          </friction>
          <bounce>
            <restitution_coefficient>0.01</restitution_coefficient>
            <threshold>0</threshold>
          </bounce>
        </surface>
      </collision>
      <visual name='r2_F_roller_link_visual'>
        <pose>0 0 0 0 -0 0</pose>
        <geometry>
          <mesh>
            <scale>1 1 1</scale>
            <uri>model://rs_robot/meshes/DAE/roller/roller.dae</uri>
          </mesh>
        </geometry>
      </visual>
    </link>
    <joint name='r3_F_roller_joint' type='revolute'>
      <pose relative_to='first_wheel_link'>-0.014144 -0.006 -0.019467 -2.51327 -0 1.5708</pose>
      <parent>first_wheel_link</parent>
      <child>r3_F_roller_link</child>
      <axis>
        <xyz>0 1 0</xyz>
        <limit>
          <lower>-1e+16</lower>
          <upper>1e+16</upper>
        </limit>
        <dynamics>
          <spring_reference>0</spring_reference>
          <spring_stiffness>0</spring_stiffness>
        </dynamics>
      </axis>
    </joint>
    <link name='r3_F_roller_link'>
      <pose relative_to='r3_F_roller_joint'>0 0 0 0 -0 0</pose>
      <inertial>
        <pose>0 0 0 0 -0 0</pose>
        <mass>0.009</mass>
        <inertia>
          <ixx>1.257e-06</ixx>
          <ixy>0</ixy>
          <ixz>0</ixz>
          <iyy>3.42e-07</iyy>
          <iyz>0</iyz>
          <izz>1.257e-06</izz>
        </inertia>
      </inertial>
      <collision name='r3_F_roller_link_collision'>
        <pose>0 0 0 0 -0 0</pose>
        <geometry>
          <mesh>
            <scale>1 1 1</scale>
            <uri>model://rs_robot/meshes/STL/roller/roller.stl</uri>
          </mesh>
        </geometry>
        <surface>
          <contact>
            <ode>
              <max_vel>0.01</max_vel>
            </ode>
          </contact>
          <friction>
            <ode>
              <mu>1.5</mu>
              <mu2>1.5</mu2>
              <kp>1e15</kp>
              <kd>1e13</kd>
            </ode>
          </friction>
          <bounce>
            <restitution_coefficient>0.01</restitution_coefficient>
            <threshold>0</threshold>
          </bounce>
        </surface>
      </collision>
      <visual name='r3_F_roller_link_visual'>
        <pose>0 0 0 0 -0 0</pose>
        <geometry>
          <mesh>
            <scale>1 1 1</scale>
            <uri>model://rs_robot/meshes/DAE/roller/roller.dae</uri>
          </mesh>
        </geometry>
      </visual>
    </link>
    <joint name='r4_F_roller_joint' type='revolute'>
      <pose relative_to='first_wheel_link'>0.014144 -0.006 -0.019467 2.51327 -0 1.5708</pose>
      <parent>first_wheel_link</parent>
      <child>r4_F_roller_link</child>
      <axis>
        <xyz>0 1 0</xyz>
        <limit>
          <lower>-1e+16</lower>
          <upper>1e+16</upper>
        </limit>
        <dynamics>
          <spring_reference>0</spring_reference>
          <spring_stiffness>0</spring_stiffness>
        </dynamics>
      </axis>
    </joint>
    <link name='r4_F_roller_link'>
      <pose relative_to='r4_F_roller_joint'>0 0 0 0 -0 0</pose>
      <inertial>
        <pose>0 0 0 0 -0 0</pose>
        <mass>0.009</mass>
        <inertia>
          <ixx>1.257e-06</ixx>
          <ixy>0</ixy>
          <ixz>0</ixz>
          <iyy>3.42e-07</iyy>
          <iyz>0</iyz>
          <izz>1.257e-06</izz>
        </inertia>
      </inertial>
      <collision name='r4_F_roller_link_collision'>
        <pose>0 0 0 0 -0 0</pose>
        <geometry>
          <mesh>
            <scale>1 1 1</scale>
            <uri>model://rs_robot/meshes/STL/roller/roller.stl</uri>
          </mesh>
        <surface>
          <contact>
            <ode>
              <max_vel>0.01</max_vel>
            </ode>
          </contact>
          <friction>
            <ode>
              <mu>1.5</mu>
              <mu2>1.5</mu2>
              <kp>1e15</kp>
              <kd>1e13</kd>
            </ode>
          </friction>
          <bounce>
            <restitution_coefficient>0.01</restitution_coefficient>
            <threshold>0</threshold>
          </bounce>
        </surface>
        </geometry>
      </collision>
      <visual name='r4_F_roller_link_visual'>
        <pose>0 0 0 0 -0 0</pose>
        <geometry>
          <mesh>
            <scale>1 1 1</scale>
            <uri>model://rs_robot/meshes/DAE/roller/roller.dae</uri>
          </mesh>
        </geometry>
      </visual>
    </link>
    <joint name='r5_F_roller_joint' type='revolute'>
      <pose relative_to='first_wheel_link'>0.022885 -0.006 0.007436 1.25664 -0 1.5708</pose>
      <parent>first_wheel_link</parent>
      <child>r5_F_roller_link</child>
      <axis>
        <xyz>0 1 0</xyz>
        <limit>
          <lower>-1e+16</lower>
          <upper>1e+16</upper>
        </limit>
        <dynamics>
          <spring_reference>0</spring_reference>
          <spring_stiffness>0</spring_stiffness>
        </dynamics>
      </axis>
    </joint>
    <link name='r5_F_roller_link'>
      <pose relative_to='r5_F_roller_joint'>0 0 0 0 -0 0</pose>
      <inertial>
        <pose>0 0 0 0 -0 0</pose>
        <mass>0.009</mass>
        <inertia>
          <ixx>1.257e-06</ixx>
          <ixy>0</ixy>
          <ixz>0</ixz>
          <iyy>3.42e-07</iyy>
          <iyz>0</iyz>
          <izz>1.257e-06</izz>
        </inertia>
      </inertial>
      <collision name='r5_F_roller_link_collision'>
        <pose>0 0 0 0 -0 0</pose>
        <geometry>
          <mesh>
            <scale>1 1 1</scale>
            <uri>model://rs_robot/meshes/STL/roller/roller.stl</uri>
          </mesh>
        </geometry>
        <surface>
          <contact>
            <ode>
              <max_vel>0.01</max_vel>
            </ode>
          </contact>
          <friction>
            <ode>
              <mu>1.5</mu>
              <mu2>1.5</mu2>
              <kp>1e15</kp>
              <kd>1e13</kd>
            </ode>
          </friction>
          <bounce>
            <restitution_coefficient>0.01</restitution_coefficient>
            <threshold>0</threshold>
          </bounce>
        </surface>
      </collision>
      <visual name='r5_F_roller_link_visual'>
        <pose>0 0 0 0 -0 0</pose>
        <geometry>
          <mesh>
            <scale>1 1 1</scale>
            <uri>model://rs_robot/meshes/DAE/roller/roller.dae</uri>
          </mesh>
        </geometry>
      </visual>
    </link>
    <joint name='r6_F_roller_joint' type='revolute'>
      <pose relative_to='first_wheel_link'>0 0.006 -0.024063 0 -0 1.5708</pose>
      <parent>first_wheel_link</parent>
      <child>r6_F_roller_link</child>
      <axis>
        <xyz>0 1 0</xyz>
        <limit>
          <lower>-1e+16</lower>
          <upper>1e+16</upper>
        </limit>
        <dynamics>
          <spring_reference>0</spring_reference>
          <spring_stiffness>0</spring_stiffness>
        </dynamics>
      </axis>
    </joint>
    <link name='r6_F_roller_link'>
      <pose relative_to='r6_F_roller_joint'>0 0 0 0 -0 0</pose>
      <inertial>
        <pose>0 0 0 0 -0 0</pose>
        <mass>0.009</mass>
        <inertia>
          <ixx>1.257e-06</ixx>
          <ixy>0</ixy>
          <ixz>0</ixz>
          <iyy>3.42e-07</iyy>
          <iyz>0</iyz>
          <izz>1.257e-06</izz>
        </inertia>
      </inertial>
      <collision name='r6_F_roller_link_collision'>
        <pose>0 0 0 0 -0 0</pose>
        <geometry>
          <mesh>
            <scale>1 1 1</scale>
            <uri>model://rs_robot/meshes/STL/roller/roller.stl</uri>
          </mesh>
        </geometry>
        <surface>
          <contact>
            <ode>
              <max_vel>0.01</max_vel>
            </ode>
          </contact>
          <friction>
            <ode>
              <mu>1.5</mu>
              <mu2>1.5</mu2>
              <kp>1e15</kp>
              <kd>1e13</kd>
            </ode>
          </friction>
          <bounce>
            <restitution_coefficient>0.01</restitution_coefficient>
            <threshold>0</threshold>
          </bounce>
        </surface>
      </collision>
      <visual name='r6_F_roller_link_visual'>
        <pose>0 0 0 0 -0 0</pose>
        <geometry>
          <mesh>
            <scale>1 1 1</scale>
            <uri>model://rs_robot/meshes/DAE/roller/roller.dae</uri>
          </mesh>
        </geometry>
      </visual>
    </link>
    <joint name='r7_F_roller_joint' type='revolute'>
      <pose relative_to='first_wheel_link'>0.022885 0.006 -0.007436 -1.25664 -0 1.5708</pose>
      <parent>first_wheel_link</parent>
      <child>r7_F_roller_link</child>
      <axis>
        <xyz>0 1 0</xyz>
        <limit>
          <lower>-1e+16</lower>
          <upper>1e+16</upper>
        </limit>
        <dynamics>
          <spring_reference>0</spring_reference>
          <spring_stiffness>0</spring_stiffness>
        </dynamics>
      </axis>
    </joint>
    <link name='r7_F_roller_link'>
      <pose relative_to='r7_F_roller_joint'>0 0 0 0 -0 0</pose>
      <inertial>
        <pose>0 0 0 0 -0 0</pose>
        <mass>0.009</mass>
        <inertia>
          <ixx>1.257e-06</ixx>
          <ixy>0</ixy>
          <ixz>0</ixz>
          <iyy>3.42e-07</iyy>
          <iyz>0</iyz>
          <izz>1.257e-06</izz>
        </inertia>
      </inertial>
      <collision name='r7_F_roller_link_collision'>
        <pose>0 0 0 0 -0 0</pose>
        <geometry>
          <mesh>
            <scale>1 1 1</scale>
            <uri>model://rs_robot/meshes/STL/roller/roller.stl</uri>
          </mesh>
        </geometry>
        <surface>
          <contact>
            <ode>
              <max_vel>0.01</max_vel>
            </ode>
          </contact>
          <friction>
            <ode>
              <mu>1.5</mu>
              <mu2>1.5</mu2>
              <kp>1e15</kp>
              <kd>1e13</kd>
            </ode>
          </friction>
          <bounce>
            <restitution_coefficient>0.01</restitution_coefficient>
            <threshold>0</threshold>
          </bounce>
        </surface>
      </collision>
      <visual name='r7_F_roller_link_visual'>
        <pose>0 0 0 0 -0 0</pose>
        <geometry>
          <mesh>
            <scale>1 1 1</scale>
            <uri>model://rs_robot/meshes/DAE/roller/roller.dae</uri>
          </mesh>
        </geometry>
      </visual>
    </link>
    <joint name='r8_F_roller_joint' type='revolute'>
      <pose relative_to='first_wheel_link'>0.014144 0.006 0.019467 -2.51327 -0 1.5708</pose>
      <parent>first_wheel_link</parent>
      <child>r8_F_roller_link</child>
      <axis>
        <xyz>0 1 0</xyz>
        <limit>
          <lower>-1e+16</lower>
          <upper>1e+16</upper>
        </limit>
        <dynamics>
          <spring_reference>0</spring_reference>
          <spring_stiffness>0</spring_stiffness>
        </dynamics>
      </axis>
    </joint>
    <link name='r8_F_roller_link'>
      <pose relative_to='r8_F_roller_joint'>0 0 0 0 -0 0</pose>
      <inertial>
        <pose>0 0 0 0 -0 0</pose>
        <mass>0.009</mass>
        <inertia>
          <ixx>1.257e-06</ixx>
          <ixy>0</ixy>
          <ixz>0</ixz>
          <iyy>3.42e-07</iyy>
          <iyz>0</iyz>
          <izz>1.257e-06</izz>
        </inertia>
      </inertial>
      <collision name='r8_F_roller_link_collision'>
        <pose>0 0 0 0 -0 0</pose>
        <geometry>
          <mesh>
            <scale>1 1 1</scale>
            <uri>model://rs_robot/meshes/STL/roller/roller.stl</uri>
          </mesh>
        </geometry>
        <surface>
          <contact>
            <ode>
              <max_vel>0.01</max_vel>
            </ode>
          </contact>
          <friction>
            <ode>
              <mu>1.5</mu>
              <mu2>1.5</mu2>
              <kp>1e15</kp>
              <kd>1e13</kd>
            </ode>
          </friction>
          <bounce>
            <restitution_coefficient>0.01</restitution_coefficient>
            <threshold>0</threshold>
          </bounce>
        </surface>
      </collision>
      <visual name='r8_F_roller_link_visual'>
        <pose>0 0 0 0 -0 0</pose>
        <geometry>
          <mesh>
            <scale>1 1 1</scale>
            <uri>model://rs_robot/meshes/DAE/roller/roller.dae</uri>
          </mesh>
        </geometry>
      </visual>
    </link>
    <joint name='r9_F_roller_joint' type='revolute'>
      <pose relative_to='first_wheel_link'>-0.014144 0.006 0.019467 2.51327 -0 1.5708</pose>
      <parent>first_wheel_link</parent>
      <child>r9_F_roller_link</child>
      <axis>
        <xyz>0 1 0</xyz>
        <limit>
          <lower>-1e+16</lower>
          <upper>1e+16</upper>
        </limit>
        <dynamics>
          <spring_reference>0</spring_reference>
          <spring_stiffness>0</spring_stiffness>
        </dynamics>
      </axis>
    </joint>
    <link name='r9_F_roller_link'>
      <pose relative_to='r9_F_roller_joint'>0 0 0 0 -0 0</pose>
      <inertial>
        <pose>0 0 0 0 -0 0</pose>
        <mass>0.009</mass>
        <inertia>
          <ixx>1.257e-06</ixx>
          <ixy>0</ixy>
          <ixz>0</ixz>
          <iyy>3.42e-07</iyy>
          <iyz>0</iyz>
          <izz>1.257e-06</izz>
        </inertia>
      </inertial>
      <collision name='r9_F_roller_link_collision'>
        <pose>0 0 0 0 -0 0</pose>
        <geometry>
          <mesh>
            <scale>1 1 1</scale>
            <uri>model://rs_robot/meshes/STL/roller/roller.stl</uri>
          </mesh>
        </geometry>
        <surface>
          <contact>
            <ode>
              <max_vel>0.01</max_vel>
            </ode>
          </contact>
          <friction>
            <ode>
              <mu>1.5</mu>
              <mu2>1.5</mu2>
              <kp>1e15</kp>
              <kd>1e13</kd>
            </ode>
          </friction>
          <bounce>
            <restitution_coefficient>0.01</restitution_coefficient>
            <threshold>0</threshold>
          </bounce>
        </surface>
      </collision>
      <visual name='r9_F_roller_link_visual'>
        <pose>0 0 0 0 -0 0</pose>
        <geometry>
          <mesh>
            <scale>1 1 1</scale>
            <uri>model://rs_robot/meshes/DAE/roller/roller.dae</uri>
          </mesh>
        </geometry>
      </visual>
    </link>
    <joint name='fourth_wheel_joint' type='revolute'>
      <pose relative_to='base_link'>-0.086338 -0.086338 -0.022 0 -0 2.3562</pose>
      <parent>base_link</parent>
      <child>fourth_wheel_link</child>
      <axis>
        <xyz>0 1 0</xyz>
        <limit>
          <effort>100</effort>
          <velocity>100</velocity>
          <lower>-1e+16</lower>
          <upper>1e+16</upper>
        </limit>
        <dynamics>
          <spring_reference>0</spring_reference>
          <spring_stiffness>0</spring_stiffness>
        </dynamics>
      </axis>
    </joint>
    <link name='fourth_wheel_link'>
      <pose relative_to='fourth_wheel_joint'>0 0 0 0 -0 0</pose>
      <inertial>
        <pose>0 -0.011 0 0 -0 0</pose>
        <mass>0.25</mass>
        <inertia>
          <ixx>0.00031</ixx>
          <ixy>0</ixy>
          <ixz>0</ixz>
          <iyy>0.0005</iyy>
          <iyz>0</iyz>
          <izz>0.00031</izz>
        </inertia>
      </inertial>
      <collision name='fourth_wheel_link_collision'>
        <pose>0 0 0 0 -0 0</pose>
        <geometry>
          <mesh>
            <scale>1 1 1</scale>
            <uri>model://rs_robot/meshes/STL/omni_wheel/omni_wheel.stl</uri>
          </mesh>
        </geometry>
        <surface>
          <contact>
            <ode>
              <max_vel>0.01</max_vel>
            </ode>
          </contact>
          <friction>
            <ode>
              <mu>1.5</mu>
              <mu2>1.5</mu2>
              <kp>1e15</kp>
              <kd>1e13</kd>
            </ode>
          </friction>
          <bounce>
            <restitution_coefficient>0.01</restitution_coefficient>
            <threshold>0</threshold>
          </bounce>
        </surface>
      </collision>
      <visual name='fourth_wheel_link_visual'>
        <pose>0 0 0 0 -0 0</pose>
        <geometry>
          <mesh>
            <scale>1 1 1</scale>
            <uri>model://rs_robot/meshes/DAE/omni_wheel/omni_wheel.dae</uri>
          </mesh>
        </geometry>
      </visual>
      <self_collide>0</self_collide>
    </link>
    <joint name='r10_R_roller_joint' type='revolute'>
      <pose relative_to='fourth_wheel_link'>-0.022885 0.006 -0.007436 1.25664 -0 1.5708</pose>
      <parent>fourth_wheel_link</parent>
      <child>r10_R_roller_link</child>
      <axis>
        <xyz>0 1 0</xyz>
        <limit>
          <lower>-1e+16</lower>
          <upper>1e+16</upper>
        </limit>
        <dynamics>
          <spring_reference>0</spring_reference>
          <spring_stiffness>0</spring_stiffness>
        </dynamics>
      </axis>
    </joint>
    <link name='r10_R_roller_link'>
      <pose relative_to='r10_R_roller_joint'>0 0 0 0 -0 0</pose>
      <inertial>
        <pose>0 0 0 0 -0 0</pose>
        <mass>0.009</mass>
        <inertia>
          <ixx>1.257e-06</ixx>
          <ixy>0</ixy>
          <ixz>0</ixz>
          <iyy>3.42e-07</iyy>
          <iyz>0</iyz>
          <izz>1.257e-06</izz>
        </inertia>
      </inertial>
      <collision name='r10_R_roller_link_collision'>
        <pose>0 0 0 0 -0 0</pose>
        <geometry>
          <mesh>
            <scale>1 1 1</scale>
            <uri>model://rs_robot/meshes/STL/roller/roller.stl</uri>
          </mesh>
        </geometry>
        <surface>
          <contact>
            <ode>
              <max_vel>0.01</max_vel>
            </ode>
          </contact>
          <friction>
            <ode>
              <mu>1.5</mu>
              <mu2>1.5</mu2>
              <kp>1e15</kp>
              <kd>1e13</kd>
            </ode>
          </friction>
          <bounce>
            <restitution_coefficient>0.01</restitution_coefficient>
            <threshold>0</threshold>
          </bounce>
        </surface>
      </collision>
      <visual name='r10_R_roller_link_visual'>
        <pose>0 0 0 0 -0 0</pose>
        <geometry>
          <mesh>
            <scale>1 1 1</scale>
            <uri>model://rs_robot/meshes/DAE/roller/roller.dae</uri>
          </mesh>
        </geometry>
      </visual>
    </link>
    <joint name='r1_R_roller_joint' type='revolute'>
      <pose relative_to='fourth_wheel_link'>0 -0.006 0.024063 0 -0 1.5708</pose>
      <parent>fourth_wheel_link</parent>
      <child>r1_R_roller_link</child>
      <axis>
        <xyz>0 1 0</xyz>
        <limit>
          <lower>-1e+16</lower>
          <upper>1e+16</upper>
        </limit>
        <dynamics>
          <spring_reference>0</spring_reference>
          <spring_stiffness>0</spring_stiffness>
        </dynamics>
      </axis>
    </joint>
    <link name='r1_R_roller_link'>
      <pose relative_to='r1_R_roller_joint'>0 0 0 0 -0 0</pose>
      <inertial>
        <pose>0 0 0 0 -0 0</pose>
        <mass>0.009</mass>
        <inertia>
          <ixx>1.257e-06</ixx>
          <ixy>0</ixy>
          <ixz>0</ixz>
          <iyy>3.42e-07</iyy>
          <iyz>0</iyz>
          <izz>1.257e-06</izz>
        </inertia>
      </inertial>
      <collision name='r1_R_roller_link_collision'>
        <pose>0 0 0 0 -0 0</pose>
        <geometry>
          <mesh>
            <scale>1 1 1</scale>
            <uri>model://rs_robot/meshes/STL/roller/roller.stl</uri>
          </mesh>
        </geometry>
        <surface>
          <contact>
            <ode>
              <max_vel>0.01</max_vel>
            </ode>
          </contact>
          <friction>
            <ode>
              <mu>1.5</mu>
              <mu2>1.5</mu2>
              <kp>1e15</kp>
              <kd>1e13</kd>
            </ode>
          </friction>
          <bounce>
            <restitution_coefficient>0.01</restitution_coefficient>
            <threshold>0</threshold>
          </bounce>
        </surface>
      </collision>
      <visual name='r1_R_roller_link_visual'>
        <pose>0 0 0 0 -0 0</pose>
        <geometry>
          <mesh>
            <scale>1 1 1</scale>
            <uri>model://rs_robot/meshes/DAE/roller/roller.dae</uri>
          </mesh>
        </geometry>
      </visual>
    </link>
    <joint name='r2_R_roller_joint' type='revolute'>
      <pose relative_to='fourth_wheel_link'>-0.022885 -0.006 0.007436 -1.25664 -0 1.5708</pose>
      <parent>fourth_wheel_link</parent>
      <child>r2_R_roller_link</child>
      <axis>
        <xyz>0 1 0</xyz>
        <limit>
          <lower>-1e+16</lower>
          <upper>1e+16</upper>
        </limit>
        <dynamics>
          <spring_reference>0</spring_reference>
          <spring_stiffness>0</spring_stiffness>
        </dynamics>
      </axis>
    </joint>
    <link name='r2_R_roller_link'>
      <pose relative_to='r2_R_roller_joint'>0 0 0 0 -0 0</pose>
      <inertial>
        <pose>0 0 0 0 -0 0</pose>
        <mass>0.009</mass>
        <inertia>
          <ixx>1.257e-06</ixx>
          <ixy>0</ixy>
          <ixz>0</ixz>
          <iyy>3.42e-07</iyy>
          <iyz>0</iyz>
          <izz>1.257e-06</izz>
        </inertia>
      </inertial>
      <collision name='r2_R_roller_link_collision'>
        <pose>0 0 0 0 -0 0</pose>
        <geometry>
          <mesh>
            <scale>1 1 1</scale>
            <uri>model://rs_robot/meshes/STL/roller/roller.stl</uri>
          </mesh>
        </geometry>
        <surface>
          <contact>
            <ode>
              <max_vel>0.01</max_vel>
            </ode>
          </contact>
          <friction>
            <ode>
              <mu>1.5</mu>
              <mu2>1.5</mu2>
              <kp>1e15</kp>
              <kd>1e13</kd>
            </ode>
          </friction>
          <bounce>
            <restitution_coefficient>0.01</restitution_coefficient>
            <threshold>0</threshold>
          </bounce>
        </surface>
      </collision>
      <visual name='r2_R_roller_link_visual'>
        <pose>0 0 0 0 -0 0</pose>
        <geometry>
          <mesh>
            <scale>1 1 1</scale>
            <uri>model://rs_robot/meshes/DAE/roller/roller.dae</uri>
          </mesh>
        </geometry>
      </visual>
    </link>
    <joint name='r3_R_roller_joint' type='revolute'>
      <pose relative_to='fourth_wheel_link'>-0.014144 -0.006 -0.019467 -2.51327 -0 1.5708</pose>
      <parent>fourth_wheel_link</parent>
      <child>r3_R_roller_link</child>
      <axis>
        <xyz>0 1 0</xyz>
        <limit>
          <lower>-1e+16</lower>
          <upper>1e+16</upper>
        </limit>
        <dynamics>
          <spring_reference>0</spring_reference>
          <spring_stiffness>0</spring_stiffness>
        </dynamics>
      </axis>
    </joint>
    <link name='r3_R_roller_link'>
      <pose relative_to='r3_R_roller_joint'>0 0 0 0 -0 0</pose>
      <inertial>
        <pose>0 0 0 0 -0 0</pose>
        <mass>0.009</mass>
        <inertia>
          <ixx>1.257e-06</ixx>
          <ixy>0</ixy>
          <ixz>0</ixz>
          <iyy>3.42e-07</iyy>
          <iyz>0</iyz>
          <izz>1.257e-06</izz>
        </inertia>
      </inertial>
      <collision name='r3_R_roller_link_collision'>
        <pose>0 0 0 0 -0 0</pose>
        <geometry>
          <mesh>
            <scale>1 1 1</scale>
            <uri>model://rs_robot/meshes/STL/roller/roller.stl</uri>
          </mesh>
        </geometry>
        <surface>
          <contact>
            <ode>
              <max_vel>0.01</max_vel>
            </ode>
          </contact>
          <friction>
            <ode>
              <mu>1.5</mu>
              <mu2>1.5</mu2>
              <kp>1e15</kp>
              <kd>1e13</kd>
            </ode>
          </friction>
          <bounce>
            <restitution_coefficient>0.01</restitution_coefficient>
            <threshold>0</threshold>
          </bounce>
        </surface>
      </collision>
      <visual name='r3_R_roller_link_visual'>
        <pose>0 0 0 0 -0 0</pose>
        <geometry>
          <mesh>
            <scale>1 1 1</scale>
            <uri>model://rs_robot/meshes/DAE/roller/roller.dae</uri>
          </mesh>
        </geometry>
      </visual>
    </link>
    <joint name='r4_R_roller_joint' type='revolute'>
      <pose relative_to='fourth_wheel_link'>0.014144 -0.006 -0.019467 2.51327 -0 1.5708</pose>
      <parent>fourth_wheel_link</parent>
      <child>r4_R_roller_link</child>
      <axis>
        <xyz>0 1 0</xyz>
        <limit>
          <lower>-1e+16</lower>
          <upper>1e+16</upper>
        </limit>
        <dynamics>
          <spring_reference>0</spring_reference>
          <spring_stiffness>0</spring_stiffness>
        </dynamics>
      </axis>
    </joint>
    <link name='r4_R_roller_link'>
      <pose relative_to='r4_R_roller_joint'>0 0 0 0 -0 0</pose>
      <inertial>
        <pose>0 0 0 0 -0 0</pose>
        <mass>0.009</mass>
        <inertia>
          <ixx>1.257e-06</ixx>
          <ixy>0</ixy>
          <ixz>0</ixz>
          <iyy>3.42e-07</iyy>
          <iyz>0</iyz>
          <izz>1.257e-06</izz>
        </inertia>
      </inertial>
      <collision name='r4_R_roller_link_collision'>
        <pose>0 0 0 0 -0 0</pose>
        <geometry>
          <mesh>
            <scale>1 1 1</scale>
            <uri>model://rs_robot/meshes/STL/roller/roller.stl</uri>
          </mesh>
        </geometry>
        <surface>
          <contact>
            <ode>
              <max_vel>0.01</max_vel>
            </ode>
          </contact>
          <friction>
            <ode>
              <mu>1.5</mu>
              <mu2>1.5</mu2>
              <kp>1e15</kp>
              <kd>1e13</kd>
            </ode>
          </friction>
          <bounce>
            <restitution_coefficient>0.01</restitution_coefficient>
            <threshold>0</threshold>
          </bounce>
        </surface>
      </collision>
      <visual name='r4_R_roller_link_visual'>
        <pose>0 0 0 0 -0 0</pose>
        <geometry>
          <mesh>
            <scale>1 1 1</scale>
            <uri>model://rs_robot/meshes/DAE/roller/roller.dae</uri>
          </mesh>
        </geometry>
      </visual>
    </link>
    <joint name='r5_R_roller_joint' type='revolute'>
      <pose relative_to='fourth_wheel_link'>0.022885 -0.006 0.007436 1.25664 -0 1.5708</pose>
      <parent>fourth_wheel_link</parent>
      <child>r5_R_roller_link</child>
      <axis>
        <xyz>0 1 0</xyz>
        <limit>
          <lower>-1e+16</lower>
          <upper>1e+16</upper>
        </limit>
        <dynamics>
          <spring_reference>0</spring_reference>
          <spring_stiffness>0</spring_stiffness>
        </dynamics>
      </axis>
    </joint>
    <link name='r5_R_roller_link'>
      <pose relative_to='r5_R_roller_joint'>0 0 0 0 -0 0</pose>
      <inertial>
        <pose>0 0 0 0 -0 0</pose>
        <mass>0.009</mass>
        <inertia>
          <ixx>1.257e-06</ixx>
          <ixy>0</ixy>
          <ixz>0</ixz>
          <iyy>3.42e-07</iyy>
          <iyz>0</iyz>
          <izz>1.257e-06</izz>
        </inertia>
      </inertial>
      <collision name='r5_R_roller_link_collision'>
        <pose>0 0 0 0 -0 0</pose>
        <geometry>
          <mesh>
            <scale>1 1 1</scale>
            <uri>model://rs_robot/meshes/STL/roller/roller.stl</uri>
          </mesh>
        </geometry>
        <surface>
          <contact>
            <ode>
              <max_vel>0.01</max_vel>
            </ode>
          </contact>
          <friction>
            <ode>
              <mu>1.5</mu>
              <mu2>1.5</mu2>
              <kp>1e15</kp>
              <kd>1e13</kd>
            </ode>
          </friction>
          <bounce>
            <restitution_coefficient>0.01</restitution_coefficient>
            <threshold>0</threshold>
          </bounce>
        </surface>
      </collision>
      <visual name='r5_R_roller_link_visual'>
        <pose>0 0 0 0 -0 0</pose>
        <geometry>
          <mesh>
            <scale>1 1 1</scale>
            <uri>model://rs_robot/meshes/DAE/roller/roller.dae</uri>
          </mesh>
        </geometry>
      </visual>
    </link>
    <joint name='r6_R_roller_joint' type='revolute'>
      <pose relative_to='fourth_wheel_link'>0 0.006 -0.024063 0 -0 1.5708</pose>
      <parent>fourth_wheel_link</parent>
      <child>r6_R_roller_link</child>
      <axis>
        <xyz>0 1 0</xyz>
        <limit>
          <lower>-1e+16</lower>
          <upper>1e+16</upper>
        </limit>
        <dynamics>
          <spring_reference>0</spring_reference>
          <spring_stiffness>0</spring_stiffness>
        </dynamics>
      </axis>
    </joint>
    <link name='r6_R_roller_link'>
      <pose relative_to='r6_R_roller_joint'>0 0 0 0 -0 0</pose>
      <inertial>
        <pose>0 0 0 0 -0 0</pose>
        <mass>0.009</mass>
        <inertia>
          <ixx>1.257e-06</ixx>
          <ixy>0</ixy>
          <ixz>0</ixz>
          <iyy>3.42e-07</iyy>
          <iyz>0</iyz>
          <izz>1.257e-06</izz>
        </inertia>
      </inertial>
      <collision name='r6_R_roller_link_collision'>
        <pose>0 0 0 0 -0 0</pose>
        <geometry>
          <mesh>
            <scale>1 1 1</scale>
            <uri>model://rs_robot/meshes/STL/roller/roller.stl</uri>
          </mesh>
        </geometry>
        <surface>
          <contact>
            <ode>
              <max_vel>0.01</max_vel>
            </ode>
          </contact>
          <friction>
            <ode>
              <mu>1.5</mu>
              <mu2>1.5</mu2>
              <kp>1e15</kp>
              <kd>1e13</kd>
            </ode>
          </friction>
          <bounce>
            <restitution_coefficient>0.01</restitution_coefficient>
            <threshold>0</threshold>
          </bounce>
        </surface>
      </collision>
      <visual name='r6_R_roller_link_visual'>
        <pose>0 0 0 0 -0 0</pose>
        <geometry>
          <mesh>
            <scale>1 1 1</scale>
            <uri>model://rs_robot/meshes/DAE/roller/roller.dae</uri>
          </mesh>
        </geometry>
      </visual>
    </link>
    <joint name='r7_R_roller_joint' type='revolute'>
      <pose relative_to='fourth_wheel_link'>0.022885 0.006 -0.007436 -1.25664 -0 1.5708</pose>
      <parent>fourth_wheel_link</parent>
      <child>r7_R_roller_link</child>
      <axis>
        <xyz>0 1 0</xyz>
        <limit>
          <lower>-1e+16</lower>
          <upper>1e+16</upper>
        </limit>
        <dynamics>
          <spring_reference>0</spring_reference>
          <spring_stiffness>0</spring_stiffness>
        </dynamics>
      </axis>
    </joint>
    <link name='r7_R_roller_link'>
      <pose relative_to='r7_R_roller_joint'>0 0 0 0 -0 0</pose>
      <inertial>
        <pose>0 0 0 0 -0 0</pose>
        <mass>0.009</mass>
        <inertia>
          <ixx>1.257e-06</ixx>
          <ixy>0</ixy>
          <ixz>0</ixz>
          <iyy>3.42e-07</iyy>
          <iyz>0</iyz>
          <izz>1.257e-06</izz>
        </inertia>
      </inertial>
      <collision name='r7_R_roller_link_collision'>
        <pose>0 0 0 0 -0 0</pose>
        <geometry>
          <mesh>
            <scale>1 1 1</scale>
            <uri>model://rs_robot/meshes/STL/roller/roller.stl</uri>
          </mesh>
        </geometry>
        <surface>
          <contact>
            <ode>
              <max_vel>0.01</max_vel>
            </ode>
          </contact>
          <friction>
            <ode>
              <mu>1.5</mu>
              <mu2>1.5</mu2>
              <kp>1e15</kp>
              <kd>1e13</kd>
            </ode>
          </friction>
          <bounce>
            <restitution_coefficient>0.01</restitution_coefficient>
            <threshold>0</threshold>
          </bounce>
        </surface>
      </collision>
      <visual name='r7_R_roller_link_visual'>
        <pose>0 0 0 0 -0 0</pose>
        <geometry>
          <mesh>
            <scale>1 1 1</scale>
            <uri>model://rs_robot/meshes/DAE/roller/roller.dae</uri>
          </mesh>
        </geometry>
      </visual>
    </link>
    <joint name='r8_R_roller_joint' type='revolute'>
      <pose relative_to='fourth_wheel_link'>0.014144 0.006 0.019467 -2.51327 -0 1.5708</pose>
      <parent>fourth_wheel_link</parent>
      <child>r8_R_roller_link</child>
      <axis>
        <xyz>0 1 0</xyz>
        <limit>
          <lower>-1e+16</lower>
          <upper>1e+16</upper>
        </limit>
        <dynamics>
          <spring_reference>0</spring_reference>
          <spring_stiffness>0</spring_stiffness>
        </dynamics>
      </axis>
    </joint>
    <link name='r8_R_roller_link'>
      <pose relative_to='r8_R_roller_joint'>0 0 0 0 -0 0</pose>
      <inertial>
        <pose>0 0 0 0 -0 0</pose>
        <mass>0.009</mass>
        <inertia>
          <ixx>1.257e-06</ixx>
          <ixy>0</ixy>
          <ixz>0</ixz>
          <iyy>3.42e-07</iyy>
          <iyz>0</iyz>
          <izz>1.257e-06</izz>
        </inertia>
      </inertial>
      <collision name='r8_R_roller_link_collision'>
        <pose>0 0 0 0 -0 0</pose>
        <geometry>
          <mesh>
            <scale>1 1 1</scale>
            <uri>model://rs_robot/meshes/STL/roller/roller.stl</uri>
          </mesh>
        </geometry>
        <surface>
          <contact>
            <ode>
              <max_vel>0.01</max_vel>
            </ode>
          </contact>
          <friction>
            <ode>
              <mu>1.5</mu>
              <mu2>1.5</mu2>
              <kp>1e15</kp>
              <kd>1e13</kd>
            </ode>
          </friction>
          <bounce>
            <restitution_coefficient>0.01</restitution_coefficient>
            <threshold>0</threshold>
          </bounce>
        </surface>
      </collision>
      <visual name='r8_R_roller_link_visual'>
        <pose>0 0 0 0 -0 0</pose>
        <geometry>
          <mesh>
            <scale>1 1 1</scale>
            <uri>model://rs_robot/meshes/DAE/roller/roller.dae</uri>
          </mesh>
        </geometry>
      </visual>
    </link>
    <joint name='r9_R_roller_joint' type='revolute'>
      <pose relative_to='fourth_wheel_link'>-0.014144 0.006 0.019467 2.51327 -0 1.5708</pose>
      <parent>fourth_wheel_link</parent>
      <child>r9_R_roller_link</child>
      <axis>
        <xyz>0 1 0</xyz>
        <limit>
          <lower>-1e+16</lower>
          <upper>1e+16</upper>
        </limit>
        <dynamics>
          <spring_reference>0</spring_reference>
          <spring_stiffness>0</spring_stiffness>
        </dynamics>
      </axis>
    </joint>
    <link name='r9_R_roller_link'>
      <pose relative_to='r9_R_roller_joint'>0 0 0 0 -0 0</pose>
      <inertial>
        <pose>0 0 0 0 -0 0</pose>
        <mass>0.009</mass>
        <inertia>
          <ixx>1.257e-06</ixx>
          <ixy>0</ixy>
          <ixz>0</ixz>
          <iyy>3.42e-07</iyy>
          <iyz>0</iyz>
          <izz>1.257e-06</izz>
        </inertia>
      </inertial>
      <collision name='r9_R_roller_link_collision'>
        <pose>0 0 0 0 -0 0</pose>
        <geometry>
          <mesh>
            <scale>1 1 1</scale>
            <uri>model://rs_robot/meshes/STL/roller/roller.stl</uri>
          </mesh>
        </geometry>
        <surface>
          <contact>
            <ode>
              <max_vel>0.01</max_vel>
            </ode>
          </contact>
          <friction>
            <ode>
              <mu>1.5</mu>
              <mu2>1.5</mu2>
              <kp>1e15</kp>
              <kd>1e13</kd>
            </ode>
          </friction>
          <bounce>
            <restitution_coefficient>0.01</restitution_coefficient>
            <threshold>0</threshold>
          </bounce>
        </surface>
      </collision>
      <visual name='r9_R_roller_link_visual'>
        <pose>0 0 0 0 -0 0</pose>
        <geometry>
          <mesh>
            <scale>1 1 1</scale>
            <uri>model://rs_robot/meshes/DAE/roller/roller.dae</uri>
          </mesh>
        </geometry>
      </visual>
    </link>
    <joint name='second_wheel_joint' type='revolute'>
      <pose relative_to='base_link'>0.086338 0.086338 -0.022 0 0 -0.785398</pose>
      <parent>base_link</parent>
      <child>second_wheel_link</child>
      <axis>
        <xyz>0 1 0</xyz>
        <limit>
          <effort>100</effort>
          <velocity>100</velocity>
          <lower>-1e+16</lower>
          <upper>1e+16</upper>
        </limit>
        <dynamics>
          <spring_reference>0</spring_reference>
          <spring_stiffness>0</spring_stiffness>
        </dynamics>
      </axis>
    </joint>
    <link name='second_wheel_link'>
      <pose relative_to='second_wheel_joint'>0 0 0 0 -0 0</pose>
      <inertial>
        <pose>0 -0.011 0 0 -0 0</pose>
        <mass>0.25</mass>
        <inertia>
          <ixx>0.00031</ixx>
          <ixy>0</ixy>
          <ixz>0</ixz>
          <iyy>0.0005</iyy>
          <iyz>0</iyz>
          <izz>0.00031</izz>
        </inertia>
      </inertial>
      <collision name='second_wheel_link_collision'>
        <pose>0 0 0 0 -0 0</pose>
        <geometry>
          <mesh>
            <scale>1 1 1</scale>
            <uri>model://rs_robot/meshes/STL/omni_wheel/omni_wheel.stl</uri>
          </mesh>
        </geometry>
        <surface>
          <contact>
            <ode>
              <max_vel>0.01</max_vel>
            </ode>
          </contact>
          <friction>
            <ode>
              <mu>1.5</mu>
              <mu2>1.5</mu2>
              <kp>1e15</kp>
              <kd>1e13</kd>
            </ode>
          </friction>
          <bounce>
            <restitution_coefficient>0.01</restitution_coefficient>
            <threshold>0</threshold>
          </bounce>
        </surface>
      </collision>
      <visual name='second_wheel_link_visual'>
        <pose>0 0 0 0 -0 0</pose>
        <geometry>
          <mesh>
            <scale>1 1 1</scale>
            <uri>model://rs_robot/meshes/DAE/omni_wheel/omni_wheel.dae</uri>
          </mesh>
        </geometry>
      </visual>
      <self_collide>0</self_collide>
    </link>
    <joint name='r10_S_roller_joint' type='revolute'>
      <pose relative_to='second_wheel_link'>-0.022885 0.006 -0.007436 1.25664 -0 1.5708</pose>
      <parent>second_wheel_link</parent>
      <child>r10_S_roller_link</child>
      <axis>
        <xyz>0 1 0</xyz>
        <limit>
          <lower>-1e+16</lower>
          <upper>1e+16</upper>
        </limit>
        <dynamics>
          <spring_reference>0</spring_reference>
          <spring_stiffness>0</spring_stiffness>
        </dynamics>
      </axis>
    </joint>
    <link name='r10_S_roller_link'>
      <pose relative_to='r10_S_roller_joint'>0 0 0 0 -0 0</pose>
      <inertial>
        <pose>0 0 0 0 -0 0</pose>
        <mass>0.009</mass>
        <inertia>
          <ixx>1.257e-06</ixx>
          <ixy>0</ixy>
          <ixz>0</ixz>
          <iyy>3.42e-07</iyy>
          <iyz>0</iyz>
          <izz>1.257e-06</izz>
        </inertia>
      </inertial>
      <collision name='r10_S_roller_link_collision'>
        <pose>0 0 0 0 -0 0</pose>
        <geometry>
          <mesh>
            <scale>1 1 1</scale>
            <uri>model://rs_robot/meshes/STL/roller/roller.stl</uri>
          </mesh>
        </geometry>
        <surface>
          <contact>
            <ode>
              <max_vel>0.01</max_vel>
            </ode>
          </contact>
          <friction>
            <ode>
              <mu>1.5</mu>
              <mu2>1.5</mu2>
              <kp>1e15</kp>
              <kd>1e13</kd>
            </ode>
          </friction>
          <bounce>
            <restitution_coefficient>0.01</restitution_coefficient>
            <threshold>0</threshold>
          </bounce>
        </surface>
      </collision>
      <visual name='r10_S_roller_link_visual'>
        <pose>0 0 0 0 -0 0</pose>
        <geometry>
          <mesh>
            <scale>1 1 1</scale>
            <uri>model://rs_robot/meshes/DAE/roller/roller.dae</uri>
          </mesh>
        </geometry>
      </visual>
    </link>
    <joint name='r1_S_roller_joint' type='revolute'>
      <pose relative_to='second_wheel_link'>0 -0.006 0.024063 0 -0 1.5708</pose>
      <parent>second_wheel_link</parent>
      <child>r1_S_roller_link</child>
      <axis>
        <xyz>0 1 0</xyz>
        <limit>
          <lower>-1e+16</lower>
          <upper>1e+16</upper>
        </limit>
        <dynamics>
          <spring_reference>0</spring_reference>
          <spring_stiffness>0</spring_stiffness>
        </dynamics>
      </axis>
    </joint>
    <link name='r1_S_roller_link'>
      <pose relative_to='r1_S_roller_joint'>0 0 0 0 -0 0</pose>
      <inertial>
        <pose>0 0 0 0 -0 0</pose>
        <mass>0.009</mass>
        <inertia>
          <ixx>1.257e-06</ixx>
          <ixy>0</ixy>
          <ixz>0</ixz>
          <iyy>3.42e-07</iyy>
          <iyz>0</iyz>
          <izz>1.257e-06</izz>
        </inertia>
      </inertial>
      <collision name='r1_S_roller_link_collision'>
        <pose>0 0 0 0 -0 0</pose>
        <geometry>
          <mesh>
            <scale>1 1 1</scale>
            <uri>model://rs_robot/meshes/STL/roller/roller.stl</uri>
          </mesh>
        </geometry>
        <surface>
          <contact>
            <ode>
              <max_vel>0.01</max_vel>
            </ode>
          </contact>
          <friction>
            <ode>
              <mu>1.5</mu>
              <mu2>1.5</mu2>
              <kp>1e15</kp>
              <kd>1e13</kd>
            </ode>
          </friction>
          <bounce>
            <restitution_coefficient>0.01</restitution_coefficient>
            <threshold>0</threshold>
          </bounce>
        </surface>
      </collision>
      <visual name='r1_S_roller_link_visual'>
        <pose>0 0 0 0 -0 0</pose>
        <geometry>
          <mesh>
            <scale>1 1 1</scale>
            <uri>model://rs_robot/meshes/DAE/roller/roller.dae</uri>
          </mesh>
        </geometry>
      </visual>
    </link>
    <joint name='r2_S_roller_joint' type='revolute'>
      <pose relative_to='second_wheel_link'>-0.022885 -0.006 0.007436 -1.25664 -0 1.5708</pose>
      <parent>second_wheel_link</parent>
      <child>r2_S_roller_link</child>
      <axis>
        <xyz>0 1 0</xyz>
        <limit>
          <lower>-1e+16</lower>
          <upper>1e+16</upper>
        </limit>
        <dynamics>
          <spring_reference>0</spring_reference>
          <spring_stiffness>0</spring_stiffness>
        </dynamics>
      </axis>
    </joint>
    <link name='r2_S_roller_link'>
      <pose relative_to='r2_S_roller_joint'>0 0 0 0 -0 0</pose>
      <inertial>
        <pose>0 0 0 0 -0 0</pose>
        <mass>0.009</mass>
        <inertia>
          <ixx>1.257e-06</ixx>
          <ixy>0</ixy>
          <ixz>0</ixz>
          <iyy>3.42e-07</iyy>
          <iyz>0</iyz>
          <izz>1.257e-06</izz>
        </inertia>
      </inertial>
      <collision name='r2_S_roller_link_collision'>
        <pose>0 0 0 0 -0 0</pose>
        <geometry>
          <mesh>
            <scale>1 1 1</scale>
            <uri>model://rs_robot/meshes/STL/roller/roller.stl</uri>
          </mesh>
        </geometry>
        <surface>
          <contact>
            <ode>
              <max_vel>0.01</max_vel>
            </ode>
          </contact>
          <friction>
            <ode>
              <mu>1.5</mu>
              <mu2>1.5</mu2>
              <kp>1e15</kp>
              <kd>1e13</kd>
            </ode>
          </friction>
          <bounce>
            <restitution_coefficient>0.01</restitution_coefficient>
            <threshold>0</threshold>
          </bounce>
        </surface>
      </collision>
      <visual name='r2_S_roller_link_visual'>
        <pose>0 0 0 0 -0 0</pose>
        <geometry>
          <mesh>
            <scale>1 1 1</scale>
            <uri>model://rs_robot/meshes/DAE/roller/roller.dae</uri>
          </mesh>
        </geometry>
      </visual>
    </link>
    <joint name='r3_S_roller_joint' type='revolute'>
      <pose relative_to='second_wheel_link'>-0.014144 -0.006 -0.019467 -2.51327 -0 1.5708</pose>
      <parent>second_wheel_link</parent>
      <child>r3_S_roller_link</child>
      <axis>
        <xyz>0 1 0</xyz>
        <limit>
          <lower>-1e+16</lower>
          <upper>1e+16</upper>
        </limit>
        <dynamics>
          <spring_reference>0</spring_reference>
          <spring_stiffness>0</spring_stiffness>
        </dynamics>
      </axis>
    </joint>
    <link name='r3_S_roller_link'>
      <pose relative_to='r3_S_roller_joint'>0 0 0 0 -0 0</pose>
      <inertial>
        <pose>0 0 0 0 -0 0</pose>
        <mass>0.009</mass>
        <inertia>
          <ixx>1.257e-06</ixx>
          <ixy>0</ixy>
          <ixz>0</ixz>
          <iyy>3.42e-07</iyy>
          <iyz>0</iyz>
          <izz>1.257e-06</izz>
        </inertia>
      </inertial>
      <collision name='r3_S_roller_link_collision'>
        <pose>0 0 0 0 -0 0</pose>
        <geometry>
          <mesh>
            <scale>1 1 1</scale>
            <uri>model://rs_robot/meshes/STL/roller/roller.stl</uri>
          </mesh>
        </geometry>
        <surface>
          <contact>
            <ode>
              <max_vel>0.01</max_vel>
            </ode>
          </contact>
          <friction>
            <ode>
              <mu>1.5</mu>
              <mu2>1.5</mu2>
              <kp>1e15</kp>
              <kd>1e13</kd>
            </ode>
          </friction>
          <bounce>
            <restitution_coefficient>0.01</restitution_coefficient>
            <threshold>0</threshold>
          </bounce>
        </surface>
      </collision>
      <visual name='r3_S_roller_link_visual'>
        <pose>0 0 0 0 -0 0</pose>
        <geometry>
          <mesh>
            <scale>1 1 1</scale>
            <uri>model://rs_robot/meshes/DAE/roller/roller.dae</uri>
          </mesh>
        </geometry>
      </visual>
    </link>
    <joint name='r4_S_roller_joint' type='revolute'>
      <pose relative_to='second_wheel_link'>0.014144 -0.006 -0.019467 2.51327 -0 1.5708</pose>
      <parent>second_wheel_link</parent>
      <child>r4_S_roller_link</child>
      <axis>
        <xyz>0 1 0</xyz>
        <limit>
          <lower>-1e+16</lower>
          <upper>1e+16</upper>
        </limit>
        <dynamics>
          <spring_reference>0</spring_reference>
          <spring_stiffness>0</spring_stiffness>
        </dynamics>
      </axis>
    </joint>
    <link name='r4_S_roller_link'>
      <pose relative_to='r4_S_roller_joint'>0 0 0 0 -0 0</pose>
      <inertial>
        <pose>0 0 0 0 -0 0</pose>
        <mass>0.009</mass>
        <inertia>
          <ixx>1.257e-06</ixx>
          <ixy>0</ixy>
          <ixz>0</ixz>
          <iyy>3.42e-07</iyy>
          <iyz>0</iyz>
          <izz>1.257e-06</izz>
        </inertia>
      </inertial>
      <collision name='r4_S_roller_link_collision'>
        <pose>0 0 0 0 -0 0</pose>
        <geometry>
          <mesh>
            <scale>1 1 1</scale>
            <uri>model://rs_robot/meshes/STL/roller/roller.stl</uri>
          </mesh>
        </geometry>
        <surface>
          <contact>
            <ode>
              <max_vel>0.01</max_vel>
            </ode>
          </contact>
          <friction>
            <ode>
              <mu>1.5</mu>
              <mu2>1.5</mu2>
              <kp>1e15</kp>
              <kd>1e13</kd>
            </ode>
          </friction>
          <bounce>
            <restitution_coefficient>0.01</restitution_coefficient>
            <threshold>0</threshold>
          </bounce>
        </surface>
      </collision>
      <visual name='r4_S_roller_link_visual'>
        <pose>0 0 0 0 -0 0</pose>
        <geometry>
          <mesh>
            <scale>1 1 1</scale>
            <uri>model://rs_robot/meshes/DAE/roller/roller.dae</uri>
          </mesh>
        </geometry>
      </visual>
    </link>
    <joint name='r5_S_roller_joint' type='revolute'>
      <pose relative_to='second_wheel_link'>0.022885 -0.006 0.007436 1.25664 -0 1.5708</pose>
      <parent>second_wheel_link</parent>
      <child>r5_S_roller_link</child>
      <axis>
        <xyz>0 1 0</xyz>
        <limit>
          <lower>-1e+16</lower>
          <upper>1e+16</upper>
        </limit>
        <dynamics>
          <spring_reference>0</spring_reference>
          <spring_stiffness>0</spring_stiffness>
        </dynamics>
      </axis>
    </joint>
    <link name='r5_S_roller_link'>
      <pose relative_to='r5_S_roller_joint'>0 0 0 0 -0 0</pose>
      <inertial>
        <pose>0 0 0 0 -0 0</pose>
        <mass>0.009</mass>
        <inertia>
          <ixx>1.257e-06</ixx>
          <ixy>0</ixy>
          <ixz>0</ixz>
          <iyy>3.42e-07</iyy>
          <iyz>0</iyz>
          <izz>1.257e-06</izz>
        </inertia>
      </inertial>
      <collision name='r5_S_roller_link_collision'>
        <pose>0 0 0 0 -0 0</pose>
        <geometry>
          <mesh>
            <scale>1 1 1</scale>
            <uri>model://rs_robot/meshes/STL/roller/roller.stl</uri>
          </mesh>
        </geometry>
        <surface>
          <contact>
            <ode>
              <max_vel>0.01</max_vel>
            </ode>
          </contact>
          <friction>
            <ode>
              <mu>1.5</mu>
              <mu2>1.5</mu2>
              <kp>1e15</kp>
              <kd>1e13</kd>
            </ode>
          </friction>
          <bounce>
            <restitution_coefficient>0.01</restitution_coefficient>
            <threshold>0</threshold>
          </bounce>
        </surface>
      </collision>
      <visual name='r5_S_roller_link_visual'>
        <pose>0 0 0 0 -0 0</pose>
        <geometry>
          <mesh>
            <scale>1 1 1</scale>
            <uri>model://rs_robot/meshes/DAE/roller/roller.dae</uri>
          </mesh>
        </geometry>
      </visual>
    </link>
    <joint name='r6_S_roller_joint' type='revolute'>
      <pose relative_to='second_wheel_link'>0 0.006 -0.024063 0 -0 1.5708</pose>
      <parent>second_wheel_link</parent>
      <child>r6_S_roller_link</child>
      <axis>
        <xyz>0 1 0</xyz>
        <limit>
          <lower>-1e+16</lower>
          <upper>1e+16</upper>
        </limit>
        <dynamics>
          <spring_reference>0</spring_reference>
          <spring_stiffness>0</spring_stiffness>
        </dynamics>
      </axis>
    </joint>
    <link name='r6_S_roller_link'>
      <pose relative_to='r6_S_roller_joint'>0 0 0 0 -0 0</pose>
      <inertial>
        <pose>0 0 0 0 -0 0</pose>
        <mass>0.009</mass>
        <inertia>
          <ixx>1.257e-06</ixx>
          <ixy>0</ixy>
          <ixz>0</ixz>
          <iyy>3.42e-07</iyy>
          <iyz>0</iyz>
          <izz>1.257e-06</izz>
        </inertia>
      </inertial>
      <collision name='r6_S_roller_link_collision'>
        <pose>0 0 0 0 -0 0</pose>
        <geometry>
          <mesh>
            <scale>1 1 1</scale>
            <uri>model://rs_robot/meshes/STL/roller/roller.stl</uri>
          </mesh>
        </geometry>
        <surface>
          <contact>
            <ode>
              <max_vel>0.01</max_vel>
            </ode>
          </contact>
          <friction>
            <ode>
              <mu>1.5</mu>
              <mu2>1.5</mu2>
              <kp>1e15</kp>
              <kd>1e13</kd>
            </ode>
          </friction>
          <bounce>
            <restitution_coefficient>0.01</restitution_coefficient>
            <threshold>0</threshold>
          </bounce>
        </surface>
      </collision>
      <visual name='r6_S_roller_link_visual'>
        <pose>0 0 0 0 -0 0</pose>
        <geometry>
          <mesh>
            <scale>1 1 1</scale>
            <uri>model://rs_robot/meshes/DAE/roller/roller.dae</uri>
          </mesh>
        </geometry>
      </visual>
    </link>
    <joint name='r7_S_roller_joint' type='revolute'>
      <pose relative_to='second_wheel_link'>0.022885 0.006 -0.007436 -1.25664 -0 1.5708</pose>
      <parent>second_wheel_link</parent>
      <child>r7_S_roller_link</child>
      <axis>
        <xyz>0 1 0</xyz>
        <limit>
          <lower>-1e+16</lower>
          <upper>1e+16</upper>
        </limit>
        <dynamics>
          <spring_reference>0</spring_reference>
          <spring_stiffness>0</spring_stiffness>
        </dynamics>
      </axis>
    </joint>
    <link name='r7_S_roller_link'>
      <pose relative_to='r7_S_roller_joint'>0 0 0 0 -0 0</pose>
      <inertial>
        <pose>0 0 0 0 -0 0</pose>
        <mass>0.009</mass>
        <inertia>
          <ixx>1.257e-06</ixx>
          <ixy>0</ixy>
          <ixz>0</ixz>
          <iyy>3.42e-07</iyy>
          <iyz>0</iyz>
          <izz>1.257e-06</izz>
        </inertia>
      </inertial>
      <collision name='r7_S_roller_link_collision'>
        <pose>0 0 0 0 -0 0</pose>
        <geometry>
          <mesh>
            <scale>1 1 1</scale>
            <uri>model://rs_robot/meshes/STL/roller/roller.stl</uri>
          </mesh>
        </geometry>
        <surface>
          <contact>
            <ode>
              <max_vel>0.01</max_vel>
            </ode>
          </contact>
          <friction>
            <ode>
              <mu>1.5</mu>
              <mu2>1.5</mu2>
              <kp>1e15</kp>
              <kd>1e13</kd>
            </ode>
          </friction>
          <bounce>
            <restitution_coefficient>0.01</restitution_coefficient>
            <threshold>0</threshold>
          </bounce>
        </surface>
      </collision>
      <visual name='r7_S_roller_link_visual'>
        <pose>0 0 0 0 -0 0</pose>
        <geometry>
          <mesh>
            <scale>1 1 1</scale>
            <uri>model://rs_robot/meshes/DAE/roller/roller.dae</uri>
          </mesh>
        </geometry>
      </visual>
    </link>
    <joint name='r8_S_roller_joint' type='revolute'>
      <pose relative_to='second_wheel_link'>0.014144 0.006 0.019467 -2.51327 -0 1.5708</pose>
      <parent>second_wheel_link</parent>
      <child>r8_S_roller_link</child>
      <axis>
        <xyz>0 1 0</xyz>
        <limit>
          <lower>-1e+16</lower>
          <upper>1e+16</upper>
        </limit>
        <dynamics>
          <spring_reference>0</spring_reference>
          <spring_stiffness>0</spring_stiffness>
        </dynamics>
      </axis>
    </joint>
    <link name='r8_S_roller_link'>
      <pose relative_to='r8_S_roller_joint'>0 0 0 0 -0 0</pose>
      <inertial>
        <pose>0 0 0 0 -0 0</pose>
        <mass>0.009</mass>
        <inertia>
          <ixx>1.257e-06</ixx>
          <ixy>0</ixy>
          <ixz>0</ixz>
          <iyy>3.42e-07</iyy>
          <iyz>0</iyz>
          <izz>1.257e-06</izz>
        </inertia>
      </inertial>
      <collision name='r8_S_roller_link_collision'>
        <pose>0 0 0 0 -0 0</pose>
        <geometry>
          <mesh>
            <scale>1 1 1</scale>
            <uri>model://rs_robot/meshes/STL/roller/roller.stl</uri>
          </mesh>
        </geometry>
        <surface>
          <contact>
            <ode>
              <max_vel>0.01</max_vel>
            </ode>
          </contact>
          <friction>
            <ode>
              <mu>1.5</mu>
              <mu2>1.5</mu2>
              <kp>1e15</kp>
              <kd>1e13</kd>
            </ode>
          </friction>
          <bounce>
            <restitution_coefficient>0.01</restitution_coefficient>
            <threshold>0</threshold>
          </bounce>
        </surface>
      </collision>
      <visual name='r8_S_roller_link_visual'>
        <pose>0 0 0 0 -0 0</pose>
        <geometry>
          <mesh>
            <scale>1 1 1</scale>
            <uri>model://rs_robot/meshes/DAE/roller/roller.dae</uri>
          </mesh>
        </geometry>
      </visual>
    </link>
    <joint name='r9_S_roller_joint' type='revolute'>
      <pose relative_to='second_wheel_link'>-0.014144 0.006 0.019467 2.51327 -0 1.5708</pose>
      <parent>second_wheel_link</parent>
      <child>r9_S_roller_link</child>
      <axis>
        <xyz>0 1 0</xyz>
        <limit>
          <lower>-1e+16</lower>
          <upper>1e+16</upper>
        </limit>
        <dynamics>
          <spring_reference>0</spring_reference>
          <spring_stiffness>0</spring_stiffness>
        </dynamics>
      </axis>
    </joint>
    <link name='r9_S_roller_link'>
      <pose relative_to='r9_S_roller_joint'>0 0 0 0 -0 0</pose>
      <inertial>
        <pose>0 0 0 0 -0 0</pose>
        <mass>0.009</mass>
        <inertia>
          <ixx>1.257e-06</ixx>
          <ixy>0</ixy>
          <ixz>0</ixz>
          <iyy>3.42e-07</iyy>
          <iyz>0</iyz>
          <izz>1.257e-06</izz>
        </inertia>
      </inertial>
      <collision name='r9_S_roller_link_collision'>
        <pose>0 0 0 0 -0 0</pose>
        <geometry>
          <mesh>
            <scale>1 1 1</scale>
            <uri>model://rs_robot/meshes/STL/roller/roller.stl</uri>
          </mesh>
        </geometry>
        <surface>
          <contact>
            <ode>
              <max_vel>0.01</max_vel>
            </ode>
          </contact>
          <friction>
            <ode>
              <mu>1.5</mu>
              <mu2>1.5</mu2>
              <kp>1e15</kp>
              <kd>1e13</kd>
            </ode>
          </friction>
          <bounce>
            <restitution_coefficient>0.01</restitution_coefficient>
            <threshold>0</threshold>
          </bounce>
        </surface>
      </collision>
      <visual name='r9_S_roller_link_visual'>
        <pose>0 0 0 0 -0 0</pose>
        <geometry>
          <mesh>
            <scale>1 1 1</scale>
            <uri>model://rs_robot/meshes/DAE/roller/roller.dae</uri>
          </mesh>
        </geometry>
      </visual>
    </link>
    <joint name='third_wheel_joint' type='revolute'>
      <pose relative_to='base_link'>-0.086338 0.086338 -0.022 0 -0 0.785398</pose>
      <parent>base_link</parent>
      <child>third_wheel_link</child>
      <axis>
        <xyz>0 1 0</xyz>
        <limit>
          <effort>100</effort>
          <velocity>100</velocity>
          <lower>-1e+16</lower>
          <upper>1e+16</upper>
        </limit>
        <dynamics>
          <spring_reference>0</spring_reference>
          <spring_stiffness>0</spring_stiffness>
        </dynamics>
      </axis>
    </joint>
    <link name='third_wheel_link'>
      <pose relative_to='third_wheel_joint'>0 0 0 0 -0 0</pose>
      <inertial>
        <pose>0 -0.011 0 0 -0 0</pose>
        <mass>0.25</mass>
        <inertia>
          <ixx>0.00031</ixx>
          <ixy>0</ixy>
          <ixz>0</ixz>
          <iyy>0.0005</iyy>
          <iyz>0</iyz>
          <izz>0.00031</izz>
        </inertia>
      </inertial>
      <collision name='third_wheel_link_collision'>
        <pose>0 0 0 0 -0 0</pose>
        <geometry>
          <mesh>
            <scale>1 1 1</scale>
            <uri>model://rs_robot/meshes/STL/omni_wheel/omni_wheel.stl</uri>
          </mesh>
        </geometry>
        <surface>
          <contact>
            <ode>
              <max_vel>0.01</max_vel>
            </ode>
          </contact>
          <friction>
            <ode>
              <mu>1.5</mu>
              <mu2>1.5</mu2>
              <kp>1e15</kp>
              <kd>1e13</kd>
            </ode>
          </friction>
          <bounce>
            <restitution_coefficient>0.01</restitution_coefficient>
            <threshold>0</threshold>
          </bounce>
        </surface>
      </collision>
      <visual name='third_wheel_link_visual'>
        <pose>0 0 0 0 -0 0</pose>
        <geometry>
          <mesh>
            <scale>1 1 1</scale>
            <uri>model://rs_robot/meshes/DAE/omni_wheel/omni_wheel.dae</uri>
          </mesh>
        </geometry>
      </visual>
      <self_collide>0</self_collide>
    </link>
    <joint name='r10_T_roller_joint' type='revolute'>
      <pose relative_to='third_wheel_link'>-0.022885 0.006 -0.007436 1.25664 -0 1.5708</pose>
      <parent>third_wheel_link</parent>
      <child>r10_T_roller_link</child>
      <axis>
        <xyz>0 1 0</xyz>
        <limit>
          <lower>-1e+16</lower>
          <upper>1e+16</upper>
        </limit>
        <dynamics>
          <spring_reference>0</spring_reference>
          <spring_stiffness>0</spring_stiffness>
        </dynamics>
      </axis>
    </joint>
    <link name='r10_T_roller_link'>
      <pose relative_to='r10_T_roller_joint'>0 0 0 0 -0 0</pose>
      <inertial>
        <pose>0 0 0 0 -0 0</pose>
        <mass>0.009</mass>
        <inertia>
          <ixx>1.257e-06</ixx>
          <ixy>0</ixy>
          <ixz>0</ixz>
          <iyy>3.42e-07</iyy>
          <iyz>0</iyz>
          <izz>1.257e-06</izz>
        </inertia>
      </inertial>
      <collision name='r10_T_roller_link_collision'>
        <pose>0 0 0 0 -0 0</pose>
        <geometry>
          <mesh>
            <scale>1 1 1</scale>
            <uri>model://rs_robot/meshes/STL/roller/roller.stl</uri>
          </mesh>
        </geometry>
        <surface>
          <contact>
            <ode>
              <max_vel>0.01</max_vel>
            </ode>
          </contact>
          <friction>
            <ode>
              <mu>1.5</mu>
              <mu2>1.5</mu2>
              <kp>1e15</kp>
              <kd>1e13</kd>
            </ode>
          </friction>
          <bounce>
            <restitution_coefficient>0.01</restitution_coefficient>
            <threshold>0</threshold>
          </bounce>
        </surface>
      </collision>
      <visual name='r10_T_roller_link_visual'>
        <pose>0 0 0 0 -0 0</pose>
        <geometry>
          <mesh>
            <scale>1 1 1</scale>
            <uri>model://rs_robot/meshes/DAE/roller/roller.dae</uri>
          </mesh>
        </geometry>
      </visual>
    </link>
    <joint name='r1_T_roller_joint' type='revolute'>
      <pose relative_to='third_wheel_link'>0 -0.006 0.024063 0 -0 1.5708</pose>
      <parent>third_wheel_link</parent>
      <child>r1_T_roller_link</child>
      <axis>
        <xyz>0 1 0</xyz>
        <limit>
          <lower>-1e+16</lower>
          <upper>1e+16</upper>
        </limit>
        <dynamics>
          <spring_reference>0</spring_reference>
          <spring_stiffness>0</spring_stiffness>
        </dynamics>
      </axis>
    </joint>
    <link name='r1_T_roller_link'>
      <pose relative_to='r1_T_roller_joint'>0 0 0 0 -0 0</pose>
      <inertial>
        <pose>0 0 0 0 -0 0</pose>
        <mass>0.009</mass>
        <inertia>
          <ixx>1.257e-06</ixx>
          <ixy>0</ixy>
          <ixz>0</ixz>
          <iyy>3.42e-07</iyy>
          <iyz>0</iyz>
          <izz>1.257e-06</izz>
        </inertia>
      </inertial>
      <collision name='r1_T_roller_link_collision'>
        <pose>0 0 0 0 -0 0</pose>
        <geometry>
          <mesh>
            <scale>1 1 1</scale>
            <uri>model://rs_robot/meshes/STL/roller/roller.stl</uri>
          </mesh>
        </geometry>
        <surface>
          <contact>
            <ode>
              <max_vel>0.01</max_vel>
            </ode>
          </contact>
          <friction>
            <ode>
              <mu>1.5</mu>
              <mu2>1.5</mu2>
              <kp>1e15</kp>
              <kd>1e13</kd>
            </ode>
          </friction>
          <bounce>
            <restitution_coefficient>0.01</restitution_coefficient>
            <threshold>0</threshold>
          </bounce>
        </surface>
      </collision>
      <visual name='r1_T_roller_link_visual'>
        <pose>0 0 0 0 -0 0</pose>
        <geometry>
          <mesh>
            <scale>1 1 1</scale>
            <uri>model://rs_robot/meshes/DAE/roller/roller.dae</uri>
          </mesh>
        </geometry>
      </visual>
    </link>
    <joint name='r2_T_roller_joint' type='revolute'>
      <pose relative_to='third_wheel_link'>-0.022885 -0.006 0.007436 -1.25664 -0 1.5708</pose>
      <parent>third_wheel_link</parent>
      <child>r2_T_roller_link</child>
      <axis>
        <xyz>0 1 0</xyz>
        <limit>
          <lower>-1e+16</lower>
          <upper>1e+16</upper>
        </limit>
        <dynamics>
          <spring_reference>0</spring_reference>
          <spring_stiffness>0</spring_stiffness>
        </dynamics>
      </axis>
    </joint>
    <link name='r2_T_roller_link'>
      <pose relative_to='r2_T_roller_joint'>0 0 0 0 -0 0</pose>
      <inertial>
        <pose>0 0 0 0 -0 0</pose>
        <mass>0.009</mass>
        <inertia>
          <ixx>1.257e-06</ixx>
          <ixy>0</ixy>
          <ixz>0</ixz>
          <iyy>3.42e-07</iyy>
          <iyz>0</iyz>
          <izz>1.257e-06</izz>
        </inertia>
      </inertial>
      <collision name='r2_T_roller_link_collision'>
        <pose>0 0 0 0 -0 0</pose>
        <geometry>
          <mesh>
            <scale>1 1 1</scale>
            <uri>model://rs_robot/meshes/STL/roller/roller.stl</uri>
          </mesh>
        </geometry>
        <surface>
          <contact>
            <ode>
              <max_vel>0.01</max_vel>
            </ode>
          </contact>
          <friction>
            <ode>
              <mu>1.5</mu>
              <mu2>1.5</mu2>
              <kp>1e15</kp>
              <kd>1e13</kd>
            </ode>
          </friction>
          <bounce>
            <restitution_coefficient>0.01</restitution_coefficient>
            <threshold>0</threshold>
          </bounce>
        </surface>
      </collision>
      <visual name='r2_T_roller_link_visual'>
        <pose>0 0 0 0 -0 0</pose>
        <geometry>
          <mesh>
            <scale>1 1 1</scale>
            <uri>model://rs_robot/meshes/DAE/roller/roller.dae</uri>
          </mesh>
        </geometry>
      </visual>
    </link>
    <joint name='r3_T_roller_joint' type='revolute'>
      <pose relative_to='third_wheel_link'>-0.014144 -0.006 -0.019467 -2.51327 -0 1.5708</pose>
      <parent>third_wheel_link</parent>
      <child>r3_T_roller_link</child>
      <axis>
        <xyz>0 1 0</xyz>
        <limit>
          <lower>-1e+16</lower>
          <upper>1e+16</upper>
        </limit>
        <dynamics>
          <spring_reference>0</spring_reference>
          <spring_stiffness>0</spring_stiffness>
        </dynamics>
      </axis>
    </joint>
    <link name='r3_T_roller_link'>
      <pose relative_to='r3_T_roller_joint'>0 0 0 0 -0 0</pose>
      <inertial>
        <pose>0 0 0 0 -0 0</pose>
        <mass>0.009</mass>
        <inertia>
          <ixx>1.257e-06</ixx>
          <ixy>0</ixy>
          <ixz>0</ixz>
          <iyy>3.42e-07</iyy>
          <iyz>0</iyz>
          <izz>1.257e-06</izz>
        </inertia>
      </inertial>
      <collision name='r3_T_roller_link_collision'>
        <pose>0 0 0 0 -0 0</pose>
        <geometry>
          <mesh>
            <scale>1 1 1</scale>
            <uri>model://rs_robot/meshes/STL/roller/roller.stl</uri>
          </mesh>
        </geometry>
        <surface>
          <contact>
            <ode>
              <max_vel>0.01</max_vel>
            </ode>
          </contact>
          <friction>
            <ode>
              <mu>1.5</mu>
              <mu2>1.5</mu2>
              <kp>1e15</kp>
              <kd>1e13</kd>
            </ode>
          </friction>
          <bounce>
            <restitution_coefficient>0.01</restitution_coefficient>
            <threshold>0</threshold>
          </bounce>
        </surface>
      </collision>
      <visual name='r3_T_roller_link_visual'>
        <pose>0 0 0 0 -0 0</pose>
        <geometry>
          <mesh>
            <scale>1 1 1</scale>
            <uri>model://rs_robot/meshes/DAE/roller/roller.dae</uri>
          </mesh>
        </geometry>
      </visual>
    </link>
    <joint name='r4_T_roller_joint' type='revolute'>
      <pose relative_to='third_wheel_link'>0.014144 -0.006 -0.019467 2.51327 -0 1.5708</pose>
      <parent>third_wheel_link</parent>
      <child>r4_T_roller_link</child>
      <axis>
        <xyz>0 1 0</xyz>
        <limit>
          <lower>-1e+16</lower>
          <upper>1e+16</upper>
        </limit>
        <dynamics>
          <spring_reference>0</spring_reference>
          <spring_stiffness>0</spring_stiffness>
        </dynamics>
      </axis>
    </joint>
    <link name='r4_T_roller_link'>
      <pose relative_to='r4_T_roller_joint'>0 0 0 0 -0 0</pose>
      <inertial>
        <pose>0 0 0 0 -0 0</pose>
        <mass>0.009</mass>
        <inertia>
          <ixx>1.257e-06</ixx>
          <ixy>0</ixy>
          <ixz>0</ixz>
          <iyy>3.42e-07</iyy>
          <iyz>0</iyz>
          <izz>1.257e-06</izz>
        </inertia>
      </inertial>
      <collision name='r4_T_roller_link_collision'>
        <pose>0 0 0 0 -0 0</pose>
        <geometry>
          <mesh>
            <scale>1 1 1</scale>
            <uri>model://rs_robot/meshes/STL/roller/roller.stl</uri>
          </mesh>
        </geometry>
        <surface>
          <contact>
            <ode>
              <max_vel>0.01</max_vel>
            </ode>
          </contact>
          <friction>
            <ode>
              <mu>1.5</mu>
              <mu2>1.5</mu2>
              <kp>1e15</kp>
              <kd>1e13</kd>
            </ode>
          </friction>
          <bounce>
            <restitution_coefficient>0.01</restitution_coefficient>
            <threshold>0</threshold>
          </bounce>
        </surface>
      </collision>
      <visual name='r4_T_roller_link_visual'>
        <pose>0 0 0 0 -0 0</pose>
        <geometry>
          <mesh>
            <scale>1 1 1</scale>
            <uri>model://rs_robot/meshes/DAE/roller/roller.dae</uri>
          </mesh>
        </geometry>
      </visual>
    </link>
    <joint name='r5_T_roller_joint' type='revolute'>
      <pose relative_to='third_wheel_link'>0.022885 -0.006 0.007436 1.25664 -0 1.5708</pose>
      <parent>third_wheel_link</parent>
      <child>r5_T_roller_link</child>
      <axis>
        <xyz>0 1 0</xyz>
        <limit>
          <lower>-1e+16</lower>
          <upper>1e+16</upper>
        </limit>
        <dynamics>
          <spring_reference>0</spring_reference>
          <spring_stiffness>0</spring_stiffness>
        </dynamics>
      </axis>
    </joint>
    <link name='r5_T_roller_link'>
      <pose relative_to='r5_T_roller_joint'>0 0 0 0 -0 0</pose>
      <inertial>
        <pose>0 0 0 0 -0 0</pose>
        <mass>0.009</mass>
        <inertia>
          <ixx>1.257e-06</ixx>
          <ixy>0</ixy>
          <ixz>0</ixz>
          <iyy>3.42e-07</iyy>
          <iyz>0</iyz>
          <izz>1.257e-06</izz>
        </inertia>
      </inertial>
      <collision name='r5_T_roller_link_collision'>
        <pose>0 0 0 0 -0 0</pose>
        <geometry>
          <mesh>
            <scale>1 1 1</scale>
            <uri>model://rs_robot/meshes/STL/roller/roller.stl</uri>
          </mesh>
        </geometry>
        <surface>
          <contact>
            <ode>
              <max_vel>0.01</max_vel>
            </ode>
          </contact>
          <friction>
            <ode>
              <mu>1.5</mu>
              <mu2>1.5</mu2>
              <kp>1e15</kp>
              <kd>1e13</kd>
            </ode>
          </friction>
          <bounce>
            <restitution_coefficient>0.01</restitution_coefficient>
            <threshold>0</threshold>
          </bounce>
        </surface>
      </collision>
      <visual name='r5_T_roller_link_visual'>
        <pose>0 0 0 0 -0 0</pose>
        <geometry>
          <mesh>
            <scale>1 1 1</scale>
            <uri>model://rs_robot/meshes/DAE/roller/roller.dae</uri>
          </mesh>
        </geometry>
      </visual>
    </link>
    <joint name='r6_T_roller_joint' type='revolute'>
      <pose relative_to='third_wheel_link'>0 0.006 -0.024063 0 -0 1.5708</pose>
      <parent>third_wheel_link</parent>
      <child>r6_T_roller_link</child>
      <axis>
        <xyz>0 1 0</xyz>
        <limit>
          <lower>-1e+16</lower>
          <upper>1e+16</upper>
        </limit>
        <dynamics>
          <spring_reference>0</spring_reference>
          <spring_stiffness>0</spring_stiffness>
        </dynamics>
      </axis>
    </joint>
    <link name='r6_T_roller_link'>
      <pose relative_to='r6_T_roller_joint'>0 0 0 0 -0 0</pose>
      <inertial>
        <pose>0 0 0 0 -0 0</pose>
        <mass>0.009</mass>
        <inertia>
          <ixx>1.257e-06</ixx>
          <ixy>0</ixy>
          <ixz>0</ixz>
          <iyy>3.42e-07</iyy>
          <iyz>0</iyz>
          <izz>1.257e-06</izz>
        </inertia>
      </inertial>
      <collision name='r6_T_roller_link_collision'>
        <pose>0 0 0 0 -0 0</pose>
        <geometry>
          <mesh>
            <scale>1 1 1</scale>
            <uri>model://rs_robot/meshes/STL/roller/roller.stl</uri>
          </mesh>
        </geometry>
        <surface>
          <contact>
            <ode>
              <max_vel>0.01</max_vel>
            </ode>
          </contact>
          <friction>
            <ode>
              <mu>1.5</mu>
              <mu2>1.5</mu2>
              <kp>1e15</kp>
              <kd>1e13</kd>
            </ode>
          </friction>
          <bounce>
            <restitution_coefficient>0.01</restitution_coefficient>
            <threshold>0</threshold>
          </bounce>
        </surface>
      </collision>
      <visual name='r6_T_roller_link_visual'>
        <pose>0 0 0 0 -0 0</pose>
        <geometry>
          <mesh>
            <scale>1 1 1</scale>
            <uri>model://rs_robot/meshes/DAE/roller/roller.dae</uri>
          </mesh>
        </geometry>
      </visual>
    </link>
    <joint name='r7_T_roller_joint' type='revolute'>
      <pose relative_to='third_wheel_link'>0.022885 0.006 -0.007436 -1.25664 -0 1.5708</pose>
      <parent>third_wheel_link</parent>
      <child>r7_T_roller_link</child>
      <axis>
        <xyz>0 1 0</xyz>
        <limit>
          <lower>-1e+16</lower>
          <upper>1e+16</upper>
        </limit>
        <dynamics>
          <spring_reference>0</spring_reference>
          <spring_stiffness>0</spring_stiffness>
        </dynamics>
      </axis>
    </joint>
    <link name='r7_T_roller_link'>
      <pose relative_to='r7_T_roller_joint'>0 0 0 0 -0 0</pose>
      <inertial>
        <pose>0 0 0 0 -0 0</pose>
        <mass>0.009</mass>
        <inertia>
          <ixx>1.257e-06</ixx>
          <ixy>0</ixy>
          <ixz>0</ixz>
          <iyy>3.42e-07</iyy>
          <iyz>0</iyz>
          <izz>1.257e-06</izz>
        </inertia>
      </inertial>
      <collision name='r7_T_roller_link_collision'>
        <pose>0 0 0 0 -0 0</pose>
        <geometry>
          <mesh>
            <scale>1 1 1</scale>
            <uri>model://rs_robot/meshes/STL/roller/roller.stl</uri>
          </mesh>
        </geometry>
        <surface>
          <contact>
            <ode>
              <max_vel>0.01</max_vel>
            </ode>
          </contact>
          <friction>
            <ode>
              <mu>1.5</mu>
              <mu2>1.5</mu2>
              <kp>1e15</kp>
              <kd>1e13</kd>
            </ode>
          </friction>
          <bounce>
            <restitution_coefficient>0.01</restitution_coefficient>
            <threshold>0</threshold>
          </bounce>
        </surface>
      </collision>
      <visual name='r7_T_roller_link_visual'>
        <pose>0 0 0 0 -0 0</pose>
        <geometry>
          <mesh>
            <scale>1 1 1</scale>
            <uri>model://rs_robot/meshes/DAE/roller/roller.dae</uri>
          </mesh>
        </geometry>
      </visual>
    </link>
    <joint name='r8_T_roller_joint' type='revolute'>
      <pose relative_to='third_wheel_link'>0.014144 0.006 0.019467 -2.51327 -0 1.5708</pose>
      <parent>third_wheel_link</parent>
      <child>r8_T_roller_link</child>
      <axis>
        <xyz>0 1 0</xyz>
        <limit>
          <lower>-1e+16</lower>
          <upper>1e+16</upper>
        </limit>
        <dynamics>
          <spring_reference>0</spring_reference>
          <spring_stiffness>0</spring_stiffness>
        </dynamics>
      </axis>
    </joint>
    <link name='r8_T_roller_link'>
      <pose relative_to='r8_T_roller_joint'>0 0 0 0 -0 0</pose>
      <inertial>
        <pose>0 0 0 0 -0 0</pose>
        <mass>0.009</mass>
        <inertia>
          <ixx>1.257e-06</ixx>
          <ixy>0</ixy>
          <ixz>0</ixz>
          <iyy>3.42e-07</iyy>
          <iyz>0</iyz>
          <izz>1.257e-06</izz>
        </inertia>
      </inertial>
      <collision name='r8_T_roller_link_collision'>
        <pose>0 0 0 0 -0 0</pose>
        <geometry>
          <mesh>
            <scale>1 1 1</scale>
            <uri>model://rs_robot/meshes/STL/roller/roller.stl</uri>
          </mesh>
        </geometry>
        <surface>
          <contact>
            <ode>
              <max_vel>0.01</max_vel>
            </ode>
          </contact>
          <friction>
            <ode>
              <mu>1.5</mu>
              <mu2>1.5</mu2>
              <kp>1e15</kp>
              <kd>1e13</kd>
            </ode>
          </friction>
          <bounce>
            <restitution_coefficient>0.01</restitution_coefficient>
            <threshold>0</threshold>
          </bounce>
        </surface>
      </collision>
      <visual name='r8_T_roller_link_visual'>
        <pose>0 0 0 0 -0 0</pose>
        <geometry>
          <mesh>
            <scale>1 1 1</scale>
            <uri>model://rs_robot/meshes/DAE/roller/roller.dae</uri>
          </mesh>
        </geometry>
      </visual>
    </link>
    <joint name='r9_T_roller_joint' type='revolute'>
      <pose relative_to='third_wheel_link'>-0.014144 0.006 0.019467 2.51327 -0 1.5708</pose>
      <parent>third_wheel_link</parent>
      <child>r9_T_roller_link</child>
      <axis>
        <xyz>0 1 0</xyz>
        <limit>
          <lower>-1e+16</lower>
          <upper>1e+16</upper>
        </limit>
        <dynamics>
          <spring_reference>0</spring_reference>
          <spring_stiffness>0</spring_stiffness>
        </dynamics>
      </axis>
    </joint>
    <link name='r9_T_roller_link'>
      <pose relative_to='r9_T_roller_joint'>0 0 0 0 -0 0</pose>
      <inertial>
        <pose>0 0 0 0 -0 0</pose>
        <mass>0.009</mass>
        <inertia>
          <ixx>1.257e-06</ixx>
          <ixy>0</ixy>
          <ixz>0</ixz>
          <iyy>3.42e-07</iyy>
          <iyz>0</iyz>
          <izz>1.257e-06</izz>
        </inertia>
      </inertial>
      <collision name='r9_T_roller_link_collision'>
        <pose>0 0 0 0 -0 0</pose>
        <geometry>
          <mesh>
            <scale>1 1 1</scale>
            <uri>model://rs_robot/meshes/STL/roller/roller.stl</uri>
          </mesh>
        </geometry>
        <surface>
          <contact>
            <ode>
              <max_vel>0.01</max_vel>
            </ode>
          </contact>
          <friction>
            <ode>
              <mu>1.5</mu>
              <mu2>1.5</mu2>
              <kp>1e15</kp>
              <kd>1e13</kd>
            </ode>
          </friction>
          <bounce>
            <restitution_coefficient>0.01</restitution_coefficient>
            <threshold>0</threshold>
          </bounce>
        </surface>
      </collision>
      <visual name='r9_T_roller_link_visual'>
        <pose>0 0 0 0 -0 0</pose>
        <geometry>
          <mesh>
            <scale>1 1 1</scale>
            <uri>model://rs_robot/meshes/DAE/roller/roller.dae</uri>
          </mesh>
        </geometry>
      </visual>
    </link>

    <static>0</static>

    <plugin name="omni_robot_joint_state" filename="libgazebo_ros_joint_state_publisher.so">
      <ros>
          <remapping>~/out:=joint_states</remapping>
      </ros>
      <update_rate>20</update_rate>
      <joint_name>first_wheel_joint</joint_name>
      <joint_name>second_wheel_joint</joint_name>
      <joint_name>third_wheel_joint</joint_name>
      <joint_name>fourth_wheel_joint</joint_name>

      <joint_name>r1_F_roller_joint</joint_name>
      <joint_name>r2_F_roller_joint</joint_name>
      <joint_name>r3_F_roller_joint</joint_name>
      <joint_name>r4_F_roller_joint</joint_name>
      <joint_name>r5_F_roller_joint</joint_name>
      <joint_name>r6_F_roller_joint</joint_name>
      <joint_name>r7_F_roller_joint</joint_name>
      <joint_name>r8_F_roller_joint</joint_name>
      <joint_name>r9_F_roller_joint</joint_name>
      <joint_name>r10_F_roller_joint</joint_name>

      <joint_name>r1_R_roller_joint</joint_name>
      <joint_name>r2_R_roller_joint</joint_name>
      <joint_name>r3_R_roller_joint</joint_name>
      <joint_name>r4_R_roller_joint</joint_name>
      <joint_name>r5_R_roller_joint</joint_name>
      <joint_name>r6_R_roller_joint</joint_name>
      <joint_name>r7_R_roller_joint</joint_name>
      <joint_name>r8_R_roller_joint</joint_name>
      <joint_name>r9_R_roller_joint</joint_name>
      <joint_name>r10_R_roller_joint</joint_name>

      <joint_name>r1_S_roller_joint</joint_name>
      <joint_name>r2_S_roller_joint</joint_name>
      <joint_name>r3_S_roller_joint</joint_name>
      <joint_name>r4_S_roller_joint</joint_name>
      <joint_name>r5_S_roller_joint</joint_name>
      <joint_name>r6_S_roller_joint</joint_name>
      <joint_name>r7_S_roller_joint</joint_name>
      <joint_name>r8_S_roller_joint</joint_name>
      <joint_name>r9_S_roller_joint</joint_name>
      <joint_name>r10_S_roller_joint</joint_name>

      <joint_name>r1_T_roller_joint</joint_name>
      <joint_name>r2_T_roller_joint</joint_name>
      <joint_name>r3_T_roller_joint</joint_name>
      <joint_name>r4_T_roller_joint</joint_name>
      <joint_name>r5_T_roller_joint</joint_name>
      <joint_name>r6_T_roller_joint</joint_name>
      <joint_name>r7_T_roller_joint</joint_name>
      <joint_name>r8_T_roller_joint</joint_name>
      <joint_name>r9_T_roller_joint</joint_name>
      <joint_name>r10_T_roller_joint</joint_name>
    </plugin>

<ros2_control name="GazeboSystem" type="system">
    <hardware>
      <plugin>gazebo_ros2_control/GazeboSystem</plugin>
    </hardware>
    
    <joint name="first_wheel_joint">
      <command_interface name="velocity">
        <param name="min">-3.14</param>
        <param name="max">3.14</param>
      </command_interface>
      <state_interface name="velocity"/>
    </joint>

    <joint name="second_wheel_joint">
      <command_interface name="velocity">
        <param name="min">-3.14</param>
        <param name="max">3.14</param>
      </command_interface>
      <state_interface name="velocity"/>
    </joint>

    <joint name="third_wheel_joint">
      <command_interface name="velocity">
        <param name="min">-3.14</param>
        <param name="max">3.14</param>
      </command_interface>
      <state_interface name="velocity"/>
    </joint>

    <joint name="fourth_wheel_joint">
      <command_interface name="velocity">
        <param name="min">-3.14</param>
        <param name="max">3.14</param>
      </command_interface>
      <state_interface name="velocity"/>
    </joint>
  </ros2_control>

    <plugin name="gazebo_ros2_control" filename="libgazebo_ros2_control.so">
      <parameters>//root/ros2_code/humble/surround_view_ros/src/gazebo_simulation/models/rs_robot/config/controllers.yaml</parameters>
    </plugin>

  </model>
</sdf>
