<?xml version="1.0" ?>
<!-- =================================================================================== -->
<!-- |    This document was autogenerated by xacro from omni_robot.urdf.xacro          | -->
<!-- |    EDITING THIS FILE BY HAND IS NOT RECOMMENDED                                 | -->
<!-- =================================================================================== -->
<robot name="omni_robot">
  <!-- =============== Link & Joint =============== -->
  <!-- Base -->
  <link name="base_footprint"/>
  <joint name="base_link_joint" type="fixed">
    <origin rpy="0 0 0" xyz="0 0 0"/>
    <parent link="base_footprint"/>
    <child link="base_link"/>
  </joint>
  <link name="base_link">
    <visual>
      <geometry>
        <mesh filename="package://omni_robot_description/meshes/STL/base/base_link.stl"/>
      </geometry>
    </visual>
    <collision>
      <geometry>
        <mesh filename="package://omni_robot_description/meshes/STL/base/base_link.stl"/>
      </geometry>
    </collision>
    <inertial>
      <origin xyz="0 0 0"/>
      <mass value="1.167"/>
      <inertia ixx="0.0016" ixy="0" ixz="0" iyy="0.0016" iyz="0" izz="0.0032"/>
    </inertial>
    <surface>
      <friction>
        <ode>
          <mu>0.8</mu>
          <mu2>0.8</mu2>
          <kp>1e15</kp>
          <kd>1e13</kd>
        </ode>
      </friction>
      <bounce>
        <restitution_coefficient>0.01</restitution_coefficient>
        <threshold>10</threshold>
      </bounce>
      <contact>
        <ode>
          <max_vel>0.01</max_vel>
          <minDepth>0</minDepth>
          <contact_surface_layer>0</contact_surface_layer>
        </ode>
      </contact>
    </surface>
  </link>
  <joint name="first_wheel_joint" type="continuous">
    <origin rpy="0 0 -2.356194555" xyz="0.086338 -0.086338 -0.022"/>
    <parent link="base_link"/>
    <child link="first_wheel_link"/>
    <limit effort="100" velocity="100"/>
    <axis xyz="0 1 0"/>
  </joint>
  <link name="first_wheel_link">
    <visual>
      <geometry>
        <mesh filename="package://omni_robot_description/meshes/DAE/omni_wheel/omni_wheel.dae"/>
      </geometry>
    </visual>
    <collision>
      <geometry>
        <mesh filename="package://omni_robot_description/meshes/STL/omni_wheel/omni_wheel.stl"/>
      </geometry>
    </collision>
    <inertial>
      <origin xyz="0.0 -0.011 -0.0"/>
      <mass value="0.25"/>
      <inertia ixx="0.00031" ixy="0" ixz="0" iyy="0.0005" iyz="0" izz="0.00031"/>
    </inertial>
    <surface>
      <friction>
        <ode>
          <mu1>1.2</mu1>
          <mu2>1.2</mu2>
          <kp>1e15</kp>
          <kd>1e13</kd>
        </ode>
      </friction>
      <bounce>
        <restitution_coefficient>0.01</restitution_coefficient>
        <threshold>0</threshold>
      </bounce>
      <contact>
        <ode>
          <max_vel>10</max_vel>
        </ode>
      </contact>
    </surface>
  </link>
  <joint name="r1_F_roller_joint" type="continuous">
    <origin rpy="0 0 1.570796" xyz="0 -0.006 0.024063"/>
    <parent link="first_wheel_link"/>
    <child link="r1_F_roller_link"/>
    <axis xyz="0 1 0"/>
  </joint>
  <link name="r1_F_roller_link">
    <visual>
      <geometry>
        <mesh filename="package://omni_robot_description/meshes/DAE/roller/roller.dae"/>
      </geometry>
    </visual>
    <collision>
      <geometry>
        <mesh filename="package://omni_robot_description/meshes/STL/roller/roller.stl"/>
      </geometry>
    </collision>
    <inertial>
      <origin xyz="0.0 0.0 0.0"/>
      <mass value="0.009"/>
      <inertia ixx="0.000001257" ixy="0" ixz="0" iyy="0.000000342" iyz="0" izz="0.000001257"/>
    </inertial>
    <surface>
      <friction>
        <ode>
          <mu1>1.2</mu1>
          <mu2>1.2</mu2>
          <kp>1e15</kp>
          <kd>1e13</kd>
        </ode>
      </friction>
      <bounce>
        <restitution_coefficient>0.01</restitution_coefficient>
        <threshold>0</threshold>
      </bounce>
      <contact>
        <ode>
          <max_vel>10</max_vel>
        </ode>
      </contact>
    </surface>
  </link>
  <joint name="r2_F_roller_joint" type="continuous">
    <origin rpy="-1.256637 0 1.570796" xyz="-0.0228853 -0.006 0.0074359"/>
    <parent link="first_wheel_link"/>
    <child link="r2_F_roller_link"/>
    <axis xyz="0 1 0"/>
  </joint>
  <link name="r2_F_roller_link">
    <visual>
      <geometry>
        <mesh filename="package://omni_robot_description/meshes/DAE/roller/roller.dae"/>
      </geometry>
    </visual>
    <collision>
      <geometry>
        <mesh filename="package://omni_robot_description/meshes/STL/roller/roller.stl"/>
      </geometry>
    </collision>
    <inertial>
      <origin xyz="0.0 0.0 0.0"/>
      <mass value="0.009"/>
      <inertia ixx="0.000001257" ixy="0" ixz="0" iyy="0.000000342" iyz="0" izz="0.000001257"/>
    </inertial>
    <surface>
      <friction>
        <ode>
          <mu1>1.2</mu1>
          <mu2>1.2</mu2>
          <kp>1e15</kp>
          <kd>1e13</kd>
        </ode>
      </friction>
      <bounce>
        <restitution_coefficient>0.01</restitution_coefficient>
        <threshold>0</threshold>
      </bounce>
      <contact>
        <ode>
          <max_vel>10</max_vel>
        </ode>
      </contact>
    </surface>
  </link>
  <joint name="r3_F_roller_joint" type="continuous">
    <origin rpy="-2.513274 0 1.570796" xyz="-0.0141439 -0.006 -0.0194674"/>
    <parent link="first_wheel_link"/>
    <child link="r3_F_roller_link"/>
    <axis xyz="0 1 0"/>
  </joint>
  <link name="r3_F_roller_link">
    <visual>
      <geometry>
        <mesh filename="package://omni_robot_description/meshes/DAE/roller/roller.dae"/>
      </geometry>
    </visual>
    <collision>
      <geometry>
        <mesh filename="package://omni_robot_description/meshes/STL/roller/roller.stl"/>
      </geometry>
    </collision>
    <inertial>
      <origin xyz="0.0 0.0 0.0"/>
      <mass value="0.009"/>
      <inertia ixx="0.000001257" ixy="0" ixz="0" iyy="0.000000342" iyz="0" izz="0.000001257"/>
    </inertial>
    <surface>
      <friction>
        <ode>
          <mu1>1.2</mu1>
          <mu2>1.2</mu2>
          <kp>1e15</kp>
          <kd>1e13</kd>
        </ode>
      </friction>
      <bounce>
        <restitution_coefficient>0.01</restitution_coefficient>
        <threshold>0</threshold>
      </bounce>
      <contact>
        <ode>
          <max_vel>10</max_vel>
        </ode>
      </contact>
    </surface>
  </link>
  <joint name="r4_F_roller_joint" type="continuous">
    <origin rpy="-3.769911 0 1.570796" xyz="0.0141439 -0.006 -0.0194674"/>
    <parent link="first_wheel_link"/>
    <child link="r4_F_roller_link"/>
    <axis xyz="0 1 0"/>
  </joint>
  <link name="r4_F_roller_link">
    <visual>
      <geometry>
        <mesh filename="package://omni_robot_description/meshes/DAE/roller/roller.dae"/>
      </geometry>
    </visual>
    <collision>
      <geometry>
        <mesh filename="package://omni_robot_description/meshes/STL/roller/roller.stl"/>
      </geometry>
    </collision>
    <inertial>
      <origin xyz="0.0 0.0 0.0"/>
      <mass value="0.009"/>
      <inertia ixx="0.000001257" ixy="0" ixz="0" iyy="0.000000342" iyz="0" izz="0.000001257"/>
    </inertial>
    <surface>
      <friction>
        <ode>
          <mu1>1.2</mu1>
          <mu2>1.2</mu2>
          <kp>1e15</kp>
          <kd>1e13</kd>
        </ode>
      </friction>
      <bounce>
        <restitution_coefficient>0.01</restitution_coefficient>
        <threshold>0</threshold>
      </bounce>
      <contact>
        <ode>
          <max_vel>10</max_vel>
        </ode>
      </contact>
    </surface>
  </link>
  <joint name="r5_F_roller_joint" type="continuous">
    <origin rpy="-5.026548 0 1.570796" xyz="0.0228853 -0.006 0.0074359"/>
    <parent link="first_wheel_link"/>
    <child link="r5_F_roller_link"/>
    <axis xyz="0 1 0"/>
  </joint>
  <link name="r5_F_roller_link">
    <visual>
      <geometry>
        <mesh filename="package://omni_robot_description/meshes/DAE/roller/roller.dae"/>
      </geometry>
    </visual>
    <collision>
      <geometry>
        <mesh filename="package://omni_robot_description/meshes/STL/roller/roller.stl"/>
      </geometry>
    </collision>
    <inertial>
      <origin xyz="0.0 0.0 0.0"/>
      <mass value="0.009"/>
      <inertia ixx="0.000001257" ixy="0" ixz="0" iyy="0.000000342" iyz="0" izz="0.000001257"/>
    </inertial>
    <surface>
      <friction>
        <ode>
          <mu1>1.2</mu1>
          <mu2>1.2</mu2>
          <kp>1e15</kp>
          <kd>1e13</kd>
        </ode>
      </friction>
      <bounce>
        <restitution_coefficient>0.01</restitution_coefficient>
        <threshold>0</threshold>
      </bounce>
      <contact>
        <ode>
          <max_vel>10</max_vel>
        </ode>
      </contact>
    </surface>
  </link>
  <joint name="r6_F_roller_joint" type="continuous">
    <origin rpy="0 0 1.570796" xyz="0 0.006 -0.024063"/>
    <parent link="first_wheel_link"/>
    <child link="r6_F_roller_link"/>
    <axis xyz="0 1 0"/>
  </joint>
  <link name="r6_F_roller_link">
    <visual>
      <geometry>
        <mesh filename="package://omni_robot_description/meshes/DAE/roller/roller.dae"/>
      </geometry>
    </visual>
    <collision>
      <geometry>
        <mesh filename="package://omni_robot_description/meshes/STL/roller/roller.stl"/>
      </geometry>
    </collision>
    <inertial>
      <origin xyz="0.0 0.0 0.0"/>
      <mass value="0.009"/>
      <inertia ixx="0.000001257" ixy="0" ixz="0" iyy="0.000000342" iyz="0" izz="0.000001257"/>
    </inertial>
    <surface>
      <friction>
        <ode>
          <mu1>1.2</mu1>
          <mu2>1.2</mu2>
          <kp>1e15</kp>
          <kd>1e13</kd>
        </ode>
      </friction>
      <bounce>
        <restitution_coefficient>0.01</restitution_coefficient>
        <threshold>0</threshold>
      </bounce>
      <contact>
        <ode>
          <max_vel>10</max_vel>
        </ode>
      </contact>
    </surface>
  </link>
  <joint name="r7_F_roller_joint" type="continuous">
    <origin rpy="-1.256637 0 1.570796" xyz="0.0228853 0.006 -0.0074359"/>
    <parent link="first_wheel_link"/>
    <child link="r7_F_roller_link"/>
    <axis xyz="0 1 0"/>
  </joint>
  <link name="r7_F_roller_link">
    <visual>
      <geometry>
        <mesh filename="package://omni_robot_description/meshes/DAE/roller/roller.dae"/>
      </geometry>
    </visual>
    <collision>
      <geometry>
        <mesh filename="package://omni_robot_description/meshes/STL/roller/roller.stl"/>
      </geometry>
    </collision>
    <inertial>
      <origin xyz="0.0 0.0 0.0"/>
      <mass value="0.009"/>
      <inertia ixx="0.000001257" ixy="0" ixz="0" iyy="0.000000342" iyz="0" izz="0.000001257"/>
    </inertial>
    <surface>
      <friction>
        <ode>
          <mu1>1.2</mu1>
          <mu2>1.2</mu2>
          <kp>1e15</kp>
          <kd>1e13</kd>
        </ode>
      </friction>
      <bounce>
        <restitution_coefficient>0.01</restitution_coefficient>
        <threshold>0</threshold>
      </bounce>
      <contact>
        <ode>
          <max_vel>10</max_vel>
        </ode>
      </contact>
    </surface>
  </link>
  <joint name="r8_F_roller_joint" type="continuous">
    <origin rpy="-2.513274 0 1.570796" xyz="0.0141439 0.006 0.0194674"/>
    <parent link="first_wheel_link"/>
    <child link="r8_F_roller_link"/>
    <axis xyz="0 1 0"/>
  </joint>
  <link name="r8_F_roller_link">
    <visual>
      <geometry>
        <mesh filename="package://omni_robot_description/meshes/DAE/roller/roller.dae"/>
      </geometry>
    </visual>
    <collision>
      <geometry>
        <mesh filename="package://omni_robot_description/meshes/STL/roller/roller.stl"/>
      </geometry>
    </collision>
    <inertial>
      <origin xyz="0.0 0.0 0.0"/>
      <mass value="0.009"/>
      <inertia ixx="0.000001257" ixy="0" ixz="0" iyy="0.000000342" iyz="0" izz="0.000001257"/>
    </inertial>
    <surface>
      <friction>
        <ode>
          <mu1>1.2</mu1>
          <mu2>1.2</mu2>
          <kp>1e15</kp>
          <kd>1e13</kd>
        </ode>
      </friction>
      <bounce>
        <restitution_coefficient>0.01</restitution_coefficient>
        <threshold>0</threshold>
      </bounce>
      <contact>
        <ode>
          <max_vel>10</max_vel>
        </ode>
      </contact>
    </surface>
  </link>
  <joint name="r9_F_roller_joint" type="continuous">
    <origin rpy="-3.769911 0 1.570796" xyz="-0.0141439 0.006 0.0194674"/>
    <parent link="first_wheel_link"/>
    <child link="r9_F_roller_link"/>
    <axis xyz="0 1 0"/>
  </joint>
  <link name="r9_F_roller_link">
    <visual>
      <geometry>
        <mesh filename="package://omni_robot_description/meshes/DAE/roller/roller.dae"/>
      </geometry>
    </visual>
    <collision>
      <geometry>
        <mesh filename="package://omni_robot_description/meshes/STL/roller/roller.stl"/>
      </geometry>
    </collision>
    <inertial>
      <origin xyz="0.0 0.0 0.0"/>
      <mass value="0.009"/>
      <inertia ixx="0.000001257" ixy="0" ixz="0" iyy="0.000000342" iyz="0" izz="0.000001257"/>
    </inertial>
    <surface>
      <friction>
        <ode>
          <mu1>1.2</mu1>
          <mu2>1.2</mu2>
          <kp>1e15</kp>
          <kd>1e13</kd>
        </ode>
      </friction>
      <bounce>
        <restitution_coefficient>0.01</restitution_coefficient>
        <threshold>0</threshold>
      </bounce>
      <contact>
        <ode>
          <max_vel>10</max_vel>
        </ode>
      </contact>
    </surface>
  </link>
  <joint name="r10_F_roller_joint" type="continuous">
    <origin rpy="-5.026548 0 1.570796" xyz="-0.0228853 0.006 -0.0074359"/>
    <parent link="first_wheel_link"/>
    <child link="r10_F_roller_link"/>
    <axis xyz="0 1 0"/>
  </joint>
  <link name="r10_F_roller_link">
    <visual>
      <geometry>
        <mesh filename="package://omni_robot_description/meshes/DAE/roller/roller.dae"/>
      </geometry>
    </visual>
    <collision>
      <geometry>
        <mesh filename="package://omni_robot_description/meshes/STL/roller/roller.stl"/>
      </geometry>
    </collision>
    <inertial>
      <origin xyz="0.0 0.0 0.0"/>
      <mass value="0.009"/>
      <inertia ixx="0.000001257" ixy="0" ixz="0" iyy="0.000000342" iyz="0" izz="0.000001257"/>
    </inertial>
    <surface>
      <friction>
        <ode>
          <mu1>1.2</mu1>
          <mu2>1.2</mu2>
          <kp>1e15</kp>
          <kd>1e13</kd>
        </ode>
      </friction>
      <bounce>
        <restitution_coefficient>0.01</restitution_coefficient>
        <threshold>0</threshold>
      </bounce>
      <contact>
        <ode>
          <max_vel>10</max_vel>
        </ode>
      </contact>
    </surface>
  </link>
  <joint name="second_wheel_joint" type="continuous">
    <origin rpy="0 0 -0.785398185" xyz="0.086338 0.086338 -0.022"/>
    <parent link="base_link"/>
    <child link="second_wheel_link"/>
    <limit effort="100" velocity="100"/>
    <axis xyz="0 1 0"/>
  </joint>
  <link name="second_wheel_link">
    <visual>
      <geometry>
        <mesh filename="package://omni_robot_description/meshes/DAE/omni_wheel/omni_wheel.dae"/>
      </geometry>
    </visual>
    <collision>
      <geometry>
        <mesh filename="package://omni_robot_description/meshes/STL/omni_wheel/omni_wheel.stl"/>
      </geometry>
    </collision>
    <inertial>
      <origin xyz="0.0 -0.011 -0.0"/>
      <mass value="0.25"/>
      <inertia ixx="0.00031" ixy="0" ixz="0" iyy="0.0005" iyz="0" izz="0.00031"/>
    </inertial>
    <surface>
      <friction>
        <ode>
          <mu1>1.2</mu1>
          <mu2>1.2</mu2>
          <kp>1e15</kp>
          <kd>1e13</kd>
        </ode>
      </friction>
      <bounce>
        <restitution_coefficient>0.01</restitution_coefficient>
        <threshold>0</threshold>
      </bounce>
      <contact>
        <ode>
          <max_vel>10</max_vel>
        </ode>
      </contact>
    </surface>
  </link>
  <joint name="r1_S_roller_joint" type="continuous">
    <origin rpy="0 0 1.570796" xyz="0 -0.006 0.024063"/>
    <parent link="second_wheel_link"/>
    <child link="r1_S_roller_link"/>
    <axis xyz="0 1 0"/>
  </joint>
  <link name="r1_S_roller_link">
    <visual>
      <geometry>
        <mesh filename="package://omni_robot_description/meshes/DAE/roller/roller.dae"/>
      </geometry>
    </visual>
    <collision>
      <geometry>
        <mesh filename="package://omni_robot_description/meshes/STL/roller/roller.stl"/>
      </geometry>
    </collision>
    <inertial>
      <origin xyz="0.0 0.0 0.0"/>
      <mass value="0.009"/>
      <inertia ixx="0.000001257" ixy="0" ixz="0" iyy="0.000000342" iyz="0" izz="0.000001257"/>
    </inertial>
    <surface>
      <friction>
        <ode>
          <mu1>1.2</mu1>
          <mu2>1.2</mu2>
          <kp>1e15</kp>
          <kd>1e13</kd>
        </ode>
      </friction>
      <bounce>
        <restitution_coefficient>0.01</restitution_coefficient>
        <threshold>0</threshold>
      </bounce>
      <contact>
        <ode>
          <max_vel>10</max_vel>
        </ode>
      </contact>
    </surface>
  </link>
  <joint name="r2_S_roller_joint" type="continuous">
    <origin rpy="-1.256637 0 1.570796" xyz="-0.0228853 -0.006 0.0074359"/>
    <parent link="second_wheel_link"/>
    <child link="r2_S_roller_link"/>
    <axis xyz="0 1 0"/>
  </joint>
  <link name="r2_S_roller_link">
    <visual>
      <geometry>
        <mesh filename="package://omni_robot_description/meshes/DAE/roller/roller.dae"/>
      </geometry>
    </visual>
    <collision>
      <geometry>
        <mesh filename="package://omni_robot_description/meshes/STL/roller/roller.stl"/>
      </geometry>
    </collision>
    <inertial>
      <origin xyz="0.0 0.0 0.0"/>
      <mass value="0.009"/>
      <inertia ixx="0.000001257" ixy="0" ixz="0" iyy="0.000000342" iyz="0" izz="0.000001257"/>
    </inertial>
    <surface>
      <friction>
        <ode>
          <mu1>1.2</mu1>
          <mu2>1.2</mu2>
          <kp>1e15</kp>
          <kd>1e13</kd>
        </ode>
      </friction>
      <bounce>
        <restitution_coefficient>0.01</restitution_coefficient>
        <threshold>0</threshold>
      </bounce>
      <contact>
        <ode>
          <max_vel>10</max_vel>
        </ode>
      </contact>
    </surface>
  </link>
  <joint name="r3_S_roller_joint" type="continuous">
    <origin rpy="-2.513274 0 1.570796" xyz="-0.0141439 -0.006 -0.0194674"/>
    <parent link="second_wheel_link"/>
    <child link="r3_S_roller_link"/>
    <axis xyz="0 1 0"/>
  </joint>
  <link name="r3_S_roller_link">
    <visual>
      <geometry>
        <mesh filename="package://omni_robot_description/meshes/DAE/roller/roller.dae"/>
      </geometry>
    </visual>
    <collision>
      <geometry>
        <mesh filename="package://omni_robot_description/meshes/STL/roller/roller.stl"/>
      </geometry>
    </collision>
    <inertial>
      <origin xyz="0.0 0.0 0.0"/>
      <mass value="0.009"/>
      <inertia ixx="0.000001257" ixy="0" ixz="0" iyy="0.000000342" iyz="0" izz="0.000001257"/>
    </inertial>
    <surface>
      <friction>
        <ode>
          <mu1>1.2</mu1>
          <mu2>1.2</mu2>
          <kp>1e15</kp>
          <kd>1e13</kd>
        </ode>
      </friction>
      <bounce>
        <restitution_coefficient>0.01</restitution_coefficient>
        <threshold>0</threshold>
      </bounce>
      <contact>
        <ode>
          <max_vel>10</max_vel>
        </ode>
      </contact>
    </surface>
  </link>
  <joint name="r4_S_roller_joint" type="continuous">
    <origin rpy="-3.769911 0 1.570796" xyz="0.0141439 -0.006 -0.0194674"/>
    <parent link="second_wheel_link"/>
    <child link="r4_S_roller_link"/>
    <axis xyz="0 1 0"/>
  </joint>
  <link name="r4_S_roller_link">
    <visual>
      <geometry>
        <mesh filename="package://omni_robot_description/meshes/DAE/roller/roller.dae"/>
      </geometry>
    </visual>
    <collision>
      <geometry>
        <mesh filename="package://omni_robot_description/meshes/STL/roller/roller.stl"/>
      </geometry>
    </collision>
    <inertial>
      <origin xyz="0.0 0.0 0.0"/>
      <mass value="0.009"/>
      <inertia ixx="0.000001257" ixy="0" ixz="0" iyy="0.000000342" iyz="0" izz="0.000001257"/>
    </inertial>
    <surface>
      <friction>
        <ode>
          <mu1>1.2</mu1>
          <mu2>1.2</mu2>
          <kp>1e15</kp>
          <kd>1e13</kd>
        </ode>
      </friction>
      <bounce>
        <restitution_coefficient>0.01</restitution_coefficient>
        <threshold>0</threshold>
      </bounce>
      <contact>
        <ode>
          <max_vel>10</max_vel>
        </ode>
      </contact>
    </surface>
  </link>
  <joint name="r5_S_roller_joint" type="continuous">
    <origin rpy="-5.026548 0 1.570796" xyz="0.0228853 -0.006 0.0074359"/>
    <parent link="second_wheel_link"/>
    <child link="r5_S_roller_link"/>
    <axis xyz="0 1 0"/>
  </joint>
  <link name="r5_S_roller_link">
    <visual>
      <geometry>
        <mesh filename="package://omni_robot_description/meshes/DAE/roller/roller.dae"/>
      </geometry>
    </visual>
    <collision>
      <geometry>
        <mesh filename="package://omni_robot_description/meshes/STL/roller/roller.stl"/>
      </geometry>
    </collision>
    <inertial>
      <origin xyz="0.0 0.0 0.0"/>
      <mass value="0.009"/>
      <inertia ixx="0.000001257" ixy="0" ixz="0" iyy="0.000000342" iyz="0" izz="0.000001257"/>
    </inertial>
    <surface>
      <friction>
        <ode>
          <mu1>1.2</mu1>
          <mu2>1.2</mu2>
          <kp>1e15</kp>
          <kd>1e13</kd>
        </ode>
      </friction>
      <bounce>
        <restitution_coefficient>0.01</restitution_coefficient>
        <threshold>0</threshold>
      </bounce>
      <contact>
        <ode>
          <max_vel>10</max_vel>
        </ode>
      </contact>
    </surface>
  </link>
  <joint name="r6_S_roller_joint" type="continuous">
    <origin rpy="0 0 1.570796" xyz="0 0.006 -0.024063"/>
    <parent link="second_wheel_link"/>
    <child link="r6_S_roller_link"/>
    <axis xyz="0 1 0"/>
  </joint>
  <link name="r6_S_roller_link">
    <visual>
      <geometry>
        <mesh filename="package://omni_robot_description/meshes/DAE/roller/roller.dae"/>
      </geometry>
    </visual>
    <collision>
      <geometry>
        <mesh filename="package://omni_robot_description/meshes/STL/roller/roller.stl"/>
      </geometry>
    </collision>
    <inertial>
      <origin xyz="0.0 0.0 0.0"/>
      <mass value="0.009"/>
      <inertia ixx="0.000001257" ixy="0" ixz="0" iyy="0.000000342" iyz="0" izz="0.000001257"/>
    </inertial>
    <surface>
      <friction>
        <ode>
          <mu1>1.2</mu1>
          <mu2>1.2</mu2>
          <kp>1e15</kp>
          <kd>1e13</kd>
        </ode>
      </friction>
      <bounce>
        <restitution_coefficient>0.01</restitution_coefficient>
        <threshold>0</threshold>
      </bounce>
      <contact>
        <ode>
          <max_vel>10</max_vel>
        </ode>
      </contact>
    </surface>
  </link>
  <joint name="r7_S_roller_joint" type="continuous">
    <origin rpy="-1.256637 0 1.570796" xyz="0.0228853 0.006 -0.0074359"/>
    <parent link="second_wheel_link"/>
    <child link="r7_S_roller_link"/>
    <axis xyz="0 1 0"/>
  </joint>
  <link name="r7_S_roller_link">
    <visual>
      <geometry>
        <mesh filename="package://omni_robot_description/meshes/DAE/roller/roller.dae"/>
      </geometry>
    </visual>
    <collision>
      <geometry>
        <mesh filename="package://omni_robot_description/meshes/STL/roller/roller.stl"/>
      </geometry>
    </collision>
    <inertial>
      <origin xyz="0.0 0.0 0.0"/>
      <mass value="0.009"/>
      <inertia ixx="0.000001257" ixy="0" ixz="0" iyy="0.000000342" iyz="0" izz="0.000001257"/>
    </inertial>
    <surface>
      <friction>
        <ode>
          <mu1>1.2</mu1>
          <mu2>1.2</mu2>
          <kp>1e15</kp>
          <kd>1e13</kd>
        </ode>
      </friction>
      <bounce>
        <restitution_coefficient>0.01</restitution_coefficient>
        <threshold>0</threshold>
      </bounce>
      <contact>
        <ode>
          <max_vel>10</max_vel>
        </ode>
      </contact>
    </surface>
  </link>
  <joint name="r8_S_roller_joint" type="continuous">
    <origin rpy="-2.513274 0 1.570796" xyz="0.0141439 0.006 0.0194674"/>
    <parent link="second_wheel_link"/>
    <child link="r8_S_roller_link"/>
    <axis xyz="0 1 0"/>
  </joint>
  <link name="r8_S_roller_link">
    <visual>
      <geometry>
        <mesh filename="package://omni_robot_description/meshes/DAE/roller/roller.dae"/>
      </geometry>
    </visual>
    <collision>
      <geometry>
        <mesh filename="package://omni_robot_description/meshes/STL/roller/roller.stl"/>
      </geometry>
    </collision>
    <inertial>
      <origin xyz="0.0 0.0 0.0"/>
      <mass value="0.009"/>
      <inertia ixx="0.000001257" ixy="0" ixz="0" iyy="0.000000342" iyz="0" izz="0.000001257"/>
    </inertial>
    <surface>
      <friction>
        <ode>
          <mu1>1.2</mu1>
          <mu2>1.2</mu2>
          <kp>1e15</kp>
          <kd>1e13</kd>
        </ode>
      </friction>
      <bounce>
        <restitution_coefficient>0.01</restitution_coefficient>
        <threshold>0</threshold>
      </bounce>
      <contact>
        <ode>
          <max_vel>10</max_vel>
        </ode>
      </contact>
    </surface>
  </link>
  <joint name="r9_S_roller_joint" type="continuous">
    <origin rpy="-3.769911 0 1.570796" xyz="-0.0141439 0.006 0.0194674"/>
    <parent link="second_wheel_link"/>
    <child link="r9_S_roller_link"/>
    <axis xyz="0 1 0"/>
  </joint>
  <link name="r9_S_roller_link">
    <visual>
      <geometry>
        <mesh filename="package://omni_robot_description/meshes/DAE/roller/roller.dae"/>
      </geometry>
    </visual>
    <collision>
      <geometry>
        <mesh filename="package://omni_robot_description/meshes/STL/roller/roller.stl"/>
      </geometry>
    </collision>
    <inertial>
      <origin xyz="0.0 0.0 0.0"/>
      <mass value="0.009"/>
      <inertia ixx="0.000001257" ixy="0" ixz="0" iyy="0.000000342" iyz="0" izz="0.000001257"/>
    </inertial>
    <surface>
      <friction>
        <ode>
          <mu1>1.2</mu1>
          <mu2>1.2</mu2>
          <kp>1e15</kp>
          <kd>1e13</kd>
        </ode>
      </friction>
      <bounce>
        <restitution_coefficient>0.01</restitution_coefficient>
        <threshold>0</threshold>
      </bounce>
      <contact>
        <ode>
          <max_vel>10</max_vel>
        </ode>
      </contact>
    </surface>
  </link>
  <joint name="r10_S_roller_joint" type="continuous">
    <origin rpy="-5.026548 0 1.570796" xyz="-0.0228853 0.006 -0.0074359"/>
    <parent link="second_wheel_link"/>
    <child link="r10_S_roller_link"/>
    <axis xyz="0 1 0"/>
  </joint>
  <link name="r10_S_roller_link">
    <visual>
      <geometry>
        <mesh filename="package://omni_robot_description/meshes/DAE/roller/roller.dae"/>
      </geometry>
    </visual>
    <collision>
      <geometry>
        <mesh filename="package://omni_robot_description/meshes/STL/roller/roller.stl"/>
      </geometry>
    </collision>
    <inertial>
      <origin xyz="0.0 0.0 0.0"/>
      <mass value="0.009"/>
      <inertia ixx="0.000001257" ixy="0" ixz="0" iyy="0.000000342" iyz="0" izz="0.000001257"/>
    </inertial>
    <surface>
      <friction>
        <ode>
          <mu1>1.2</mu1>
          <mu2>1.2</mu2>
          <kp>1e15</kp>
          <kd>1e13</kd>
        </ode>
      </friction>
      <bounce>
        <restitution_coefficient>0.01</restitution_coefficient>
        <threshold>0</threshold>
      </bounce>
      <contact>
        <ode>
          <max_vel>10</max_vel>
        </ode>
      </contact>
    </surface>
  </link>
  <joint name="third_wheel_joint" type="continuous">
    <origin rpy="0 0 0.785398185" xyz="-0.086338 0.086338 -0.022"/>
    <parent link="base_link"/>
    <child link="third_wheel_link"/>
    <limit effort="100" velocity="100"/>
    <axis xyz="0 1 0"/>
  </joint>
  <link name="third_wheel_link">
    <visual>
      <geometry>
        <mesh filename="package://omni_robot_description/meshes/DAE/omni_wheel/omni_wheel.dae"/>
      </geometry>
    </visual>
    <collision>
      <geometry>
        <mesh filename="package://omni_robot_description/meshes/STL/omni_wheel/omni_wheel.stl"/>
      </geometry>
    </collision>
    <inertial>
      <origin xyz="0.0 -0.011 -0.0"/>
      <mass value="0.25"/>
      <inertia ixx="0.00031" ixy="0" ixz="0" iyy="0.0005" iyz="0" izz="0.00031"/>
    </inertial>
    <surface>
      <friction>
        <ode>
          <mu1>1.2</mu1>
          <mu2>1.2</mu2>
          <kp>1e15</kp>
          <kd>1e13</kd>
        </ode>
      </friction>
      <bounce>
        <restitution_coefficient>0.01</restitution_coefficient>
        <threshold>0</threshold>
      </bounce>
      <contact>
        <ode>
          <max_vel>10</max_vel>
        </ode>
      </contact>
    </surface>
  </link>
  <joint name="r1_T_roller_joint" type="continuous">
    <origin rpy="0 0 1.570796" xyz="0 -0.006 0.024063"/>
    <parent link="third_wheel_link"/>
    <child link="r1_T_roller_link"/>
    <axis xyz="0 1 0"/>
  </joint>
  <link name="r1_T_roller_link">
    <visual>
      <geometry>
        <mesh filename="package://omni_robot_description/meshes/DAE/roller/roller.dae"/>
      </geometry>
    </visual>
    <collision>
      <geometry>
        <mesh filename="package://omni_robot_description/meshes/STL/roller/roller.stl"/>
      </geometry>
    </collision>
    <inertial>
      <origin xyz="0.0 0.0 0.0"/>
      <mass value="0.009"/>
      <inertia ixx="0.000001257" ixy="0" ixz="0" iyy="0.000000342" iyz="0" izz="0.000001257"/>
    </inertial>
    <surface>
      <friction>
        <ode>
          <mu1>1.2</mu1>
          <mu2>1.2</mu2>
          <kp>1e15</kp>
          <kd>1e13</kd>
        </ode>
      </friction>
      <bounce>
        <restitution_coefficient>0.01</restitution_coefficient>
        <threshold>0</threshold>
      </bounce>
      <contact>
        <ode>
          <max_vel>10</max_vel>
        </ode>
      </contact>
    </surface>
  </link>
  <joint name="r2_T_roller_joint" type="continuous">
    <origin rpy="-1.256637 0 1.570796" xyz="-0.0228853 -0.006 0.0074359"/>
    <parent link="third_wheel_link"/>
    <child link="r2_T_roller_link"/>
    <axis xyz="0 1 0"/>
  </joint>
  <link name="r2_T_roller_link">
    <visual>
      <geometry>
        <mesh filename="package://omni_robot_description/meshes/DAE/roller/roller.dae"/>
      </geometry>
    </visual>
    <collision>
      <geometry>
        <mesh filename="package://omni_robot_description/meshes/STL/roller/roller.stl"/>
      </geometry>
    </collision>
    <inertial>
      <origin xyz="0.0 0.0 0.0"/>
      <mass value="0.009"/>
      <inertia ixx="0.000001257" ixy="0" ixz="0" iyy="0.000000342" iyz="0" izz="0.000001257"/>
    </inertial>
    <surface>
      <friction>
        <ode>
          <mu1>1.2</mu1>
          <mu2>1.2</mu2>
          <kp>1e15</kp>
          <kd>1e13</kd>
        </ode>
      </friction>
      <bounce>
        <restitution_coefficient>0.01</restitution_coefficient>
        <threshold>0</threshold>
      </bounce>
      <contact>
        <ode>
          <max_vel>10</max_vel>
        </ode>
      </contact>
    </surface>
  </link>
  <joint name="r3_T_roller_joint" type="continuous">
    <origin rpy="-2.513274 0 1.570796" xyz="-0.0141439 -0.006 -0.0194674"/>
    <parent link="third_wheel_link"/>
    <child link="r3_T_roller_link"/>
    <axis xyz="0 1 0"/>
  </joint>
  <link name="r3_T_roller_link">
    <visual>
      <geometry>
        <mesh filename="package://omni_robot_description/meshes/DAE/roller/roller.dae"/>
      </geometry>
    </visual>
    <collision>
      <geometry>
        <mesh filename="package://omni_robot_description/meshes/STL/roller/roller.stl"/>
      </geometry>
    </collision>
    <inertial>
      <origin xyz="0.0 0.0 0.0"/>
      <mass value="0.009"/>
      <inertia ixx="0.000001257" ixy="0" ixz="0" iyy="0.000000342" iyz="0" izz="0.000001257"/>
    </inertial>
    <surface>
      <friction>
        <ode>
          <mu1>1.2</mu1>
          <mu2>1.2</mu2>
          <kp>1e15</kp>
          <kd>1e13</kd>
        </ode>
      </friction>
      <bounce>
        <restitution_coefficient>0.01</restitution_coefficient>
        <threshold>0</threshold>
      </bounce>
      <contact>
        <ode>
          <max_vel>10</max_vel>
        </ode>
      </contact>
    </surface>
  </link>
  <joint name="r4_T_roller_joint" type="continuous">
    <origin rpy="-3.769911 0 1.570796" xyz="0.0141439 -0.006 -0.0194674"/>
    <parent link="third_wheel_link"/>
    <child link="r4_T_roller_link"/>
    <axis xyz="0 1 0"/>
  </joint>
  <link name="r4_T_roller_link">
    <visual>
      <geometry>
        <mesh filename="package://omni_robot_description/meshes/DAE/roller/roller.dae"/>
      </geometry>
    </visual>
    <collision>
      <geometry>
        <mesh filename="package://omni_robot_description/meshes/STL/roller/roller.stl"/>
      </geometry>
    </collision>
    <inertial>
      <origin xyz="0.0 0.0 0.0"/>
      <mass value="0.009"/>
      <inertia ixx="0.000001257" ixy="0" ixz="0" iyy="0.000000342" iyz="0" izz="0.000001257"/>
    </inertial>
    <surface>
      <friction>
        <ode>
          <mu1>1.2</mu1>
          <mu2>1.2</mu2>
          <kp>1e15</kp>
          <kd>1e13</kd>
        </ode>
      </friction>
      <bounce>
        <restitution_coefficient>0.01</restitution_coefficient>
        <threshold>0</threshold>
      </bounce>
      <contact>
        <ode>
          <max_vel>10</max_vel>
        </ode>
      </contact>
    </surface>
  </link>
  <joint name="r5_T_roller_joint" type="continuous">
    <origin rpy="-5.026548 0 1.570796" xyz="0.0228853 -0.006 0.0074359"/>
    <parent link="third_wheel_link"/>
    <child link="r5_T_roller_link"/>
    <axis xyz="0 1 0"/>
  </joint>
  <link name="r5_T_roller_link">
    <visual>
      <geometry>
        <mesh filename="package://omni_robot_description/meshes/DAE/roller/roller.dae"/>
      </geometry>
    </visual>
    <collision>
      <geometry>
        <mesh filename="package://omni_robot_description/meshes/STL/roller/roller.stl"/>
      </geometry>
    </collision>
    <inertial>
      <origin xyz="0.0 0.0 0.0"/>
      <mass value="0.009"/>
      <inertia ixx="0.000001257" ixy="0" ixz="0" iyy="0.000000342" iyz="0" izz="0.000001257"/>
    </inertial>
    <surface>
      <friction>
        <ode>
          <mu1>1.2</mu1>
          <mu2>1.2</mu2>
          <kp>1e15</kp>
          <kd>1e13</kd>
        </ode>
      </friction>
      <bounce>
        <restitution_coefficient>0.01</restitution_coefficient>
        <threshold>0</threshold>
      </bounce>
      <contact>
        <ode>
          <max_vel>10</max_vel>
        </ode>
      </contact>
    </surface>
  </link>
  <joint name="r6_T_roller_joint" type="continuous">
    <origin rpy="0 0 1.570796" xyz="0 0.006 -0.024063"/>
    <parent link="third_wheel_link"/>
    <child link="r6_T_roller_link"/>
    <axis xyz="0 1 0"/>
  </joint>
  <link name="r6_T_roller_link">
    <visual>
      <geometry>
        <mesh filename="package://omni_robot_description/meshes/DAE/roller/roller.dae"/>
      </geometry>
    </visual>
    <collision>
      <geometry>
        <mesh filename="package://omni_robot_description/meshes/STL/roller/roller.stl"/>
      </geometry>
    </collision>
    <inertial>
      <origin xyz="0.0 0.0 0.0"/>
      <mass value="0.009"/>
      <inertia ixx="0.000001257" ixy="0" ixz="0" iyy="0.000000342" iyz="0" izz="0.000001257"/>
    </inertial>
    <surface>
      <friction>
        <ode>
          <mu1>1.2</mu1>
          <mu2>1.2</mu2>
          <kp>1e15</kp>
          <kd>1e13</kd>
        </ode>
      </friction>
      <bounce>
        <restitution_coefficient>0.01</restitution_coefficient>
        <threshold>0</threshold>
      </bounce>
      <contact>
        <ode>
          <max_vel>10</max_vel>
        </ode>
      </contact>
    </surface>
  </link>
  <joint name="r7_T_roller_joint" type="continuous">
    <origin rpy="-1.256637 0 1.570796" xyz="0.0228853 0.006 -0.0074359"/>
    <parent link="third_wheel_link"/>
    <child link="r7_T_roller_link"/>
    <axis xyz="0 1 0"/>
  </joint>
  <link name="r7_T_roller_link">
    <visual>
      <geometry>
        <mesh filename="package://omni_robot_description/meshes/DAE/roller/roller.dae"/>
      </geometry>
    </visual>
    <collision>
      <geometry>
        <mesh filename="package://omni_robot_description/meshes/STL/roller/roller.stl"/>
      </geometry>
    </collision>
    <inertial>
      <origin xyz="0.0 0.0 0.0"/>
      <mass value="0.009"/>
      <inertia ixx="0.000001257" ixy="0" ixz="0" iyy="0.000000342" iyz="0" izz="0.000001257"/>
    </inertial>
    <surface>
      <friction>
        <ode>
          <mu1>1.2</mu1>
          <mu2>1.2</mu2>
          <kp>1e15</kp>
          <kd>1e13</kd>
        </ode>
      </friction>
      <bounce>
        <restitution_coefficient>0.01</restitution_coefficient>
        <threshold>0</threshold>
      </bounce>
      <contact>
        <ode>
          <max_vel>10</max_vel>
        </ode>
      </contact>
    </surface>
  </link>
  <joint name="r8_T_roller_joint" type="continuous">
    <origin rpy="-2.513274 0 1.570796" xyz="0.0141439 0.006 0.0194674"/>
    <parent link="third_wheel_link"/>
    <child link="r8_T_roller_link"/>
    <axis xyz="0 1 0"/>
  </joint>
  <link name="r8_T_roller_link">
    <visual>
      <geometry>
        <mesh filename="package://omni_robot_description/meshes/DAE/roller/roller.dae"/>
      </geometry>
    </visual>
    <collision>
      <geometry>
        <mesh filename="package://omni_robot_description/meshes/STL/roller/roller.stl"/>
      </geometry>
    </collision>
    <inertial>
      <origin xyz="0.0 0.0 0.0"/>
      <mass value="0.009"/>
      <inertia ixx="0.000001257" ixy="0" ixz="0" iyy="0.000000342" iyz="0" izz="0.000001257"/>
    </inertial>
    <surface>
      <friction>
        <ode>
          <mu1>1.2</mu1>
          <mu2>1.2</mu2>
          <kp>1e15</kp>
          <kd>1e13</kd>
        </ode>
      </friction>
      <bounce>
        <restitution_coefficient>0.01</restitution_coefficient>
        <threshold>0</threshold>
      </bounce>
      <contact>
        <ode>
          <max_vel>10</max_vel>
        </ode>
      </contact>
    </surface>
  </link>
  <joint name="r9_T_roller_joint" type="continuous">
    <origin rpy="-3.769911 0 1.570796" xyz="-0.0141439 0.006 0.0194674"/>
    <parent link="third_wheel_link"/>
    <child link="r9_T_roller_link"/>
    <axis xyz="0 1 0"/>
  </joint>
  <link name="r9_T_roller_link">
    <visual>
      <geometry>
        <mesh filename="package://omni_robot_description/meshes/DAE/roller/roller.dae"/>
      </geometry>
    </visual>
    <collision>
      <geometry>
        <mesh filename="package://omni_robot_description/meshes/STL/roller/roller.stl"/>
      </geometry>
    </collision>
    <inertial>
      <origin xyz="0.0 0.0 0.0"/>
      <mass value="0.009"/>
      <inertia ixx="0.000001257" ixy="0" ixz="0" iyy="0.000000342" iyz="0" izz="0.000001257"/>
    </inertial>
    <surface>
      <friction>
        <ode>
          <mu1>1.2</mu1>
          <mu2>1.2</mu2>
          <kp>1e15</kp>
          <kd>1e13</kd>
        </ode>
      </friction>
      <bounce>
        <restitution_coefficient>0.01</restitution_coefficient>
        <threshold>0</threshold>
      </bounce>
      <contact>
        <ode>
          <max_vel>10</max_vel>
        </ode>
      </contact>
    </surface>
  </link>
  <joint name="r10_T_roller_joint" type="continuous">
    <origin rpy="-5.026548 0 1.570796" xyz="-0.0228853 0.006 -0.0074359"/>
    <parent link="third_wheel_link"/>
    <child link="r10_T_roller_link"/>
    <axis xyz="0 1 0"/>
  </joint>
  <link name="r10_T_roller_link">
    <visual>
      <geometry>
        <mesh filename="package://omni_robot_description/meshes/DAE/roller/roller.dae"/>
      </geometry>
    </visual>
    <collision>
      <geometry>
        <mesh filename="package://omni_robot_description/meshes/STL/roller/roller.stl"/>
      </geometry>
    </collision>
    <inertial>
      <origin xyz="0.0 0.0 0.0"/>
      <mass value="0.009"/>
      <inertia ixx="0.000001257" ixy="0" ixz="0" iyy="0.000000342" iyz="0" izz="0.000001257"/>
    </inertial>
    <surface>
      <friction>
        <ode>
          <mu1>1.2</mu1>
          <mu2>1.2</mu2>
          <kp>1e15</kp>
          <kd>1e13</kd>
        </ode>
      </friction>
      <bounce>
        <restitution_coefficient>0.01</restitution_coefficient>
        <threshold>0</threshold>
      </bounce>
      <contact>
        <ode>
          <max_vel>10</max_vel>
        </ode>
      </contact>
    </surface>
  </link>
  <joint name="fourth_wheel_joint" type="continuous">
    <origin rpy="0 0 2.356194555" xyz="-0.086338 -0.086338 -0.022"/>
    <parent link="base_link"/>
    <child link="fourth_wheel_link"/>
    <limit effort="100" velocity="100"/>
    <axis xyz="0 1 0"/>
  </joint>
  <link name="fourth_wheel_link">
    <visual>
      <geometry>
        <mesh filename="package://omni_robot_description/meshes/DAE/omni_wheel/omni_wheel.dae"/>
      </geometry>
    </visual>
    <collision>
      <geometry>
        <mesh filename="package://omni_robot_description/meshes/STL/omni_wheel/omni_wheel.stl"/>
      </geometry>
    </collision>
    <inertial>
      <origin xyz="0.0 -0.011 -0.0"/>
      <mass value="0.25"/>
      <inertia ixx="0.00031" ixy="0" ixz="0" iyy="0.0005" iyz="0" izz="0.00031"/>
    </inertial>
    <surface>
      <friction>
        <ode>
          <mu1>1.2</mu1>
          <mu2>1.2</mu2>
          <kp>1e15</kp>
          <kd>1e13</kd>
        </ode>
      </friction>
      <bounce>
        <restitution_coefficient>0.01</restitution_coefficient>
        <threshold>0</threshold>
      </bounce>
      <contact>
        <ode>
          <max_vel>10</max_vel>
        </ode>
      </contact>
    </surface>
  </link>
  <joint name="r1_R_roller_joint" type="continuous">
    <origin rpy="0 0 1.570796" xyz="0 -0.006 0.024063"/>
    <parent link="fourth_wheel_link"/>
    <child link="r1_R_roller_link"/>
    <axis xyz="0 1 0"/>
  </joint>
  <link name="r1_R_roller_link">
    <visual>
      <geometry>
        <mesh filename="package://omni_robot_description/meshes/DAE/roller/roller.dae"/>
      </geometry>
    </visual>
    <collision>
      <geometry>
        <mesh filename="package://omni_robot_description/meshes/STL/roller/roller.stl"/>
      </geometry>
    </collision>
    <inertial>
      <origin xyz="0.0 0.0 0.0"/>
      <mass value="0.009"/>
      <inertia ixx="0.000001257" ixy="0" ixz="0" iyy="0.000000342" iyz="0" izz="0.000001257"/>
    </inertial>
    <surface>
      <friction>
        <ode>
          <mu1>1.2</mu1>
          <mu2>1.2</mu2>
          <kp>1e15</kp>
          <kd>1e13</kd>
        </ode>
      </friction>
      <bounce>
        <restitution_coefficient>0.01</restitution_coefficient>
        <threshold>0</threshold>
      </bounce>
      <contact>
        <ode>
          <max_vel>10</max_vel>
        </ode>
      </contact>
    </surface>
  </link>
  <joint name="r2_R_roller_joint" type="continuous">
    <origin rpy="-1.256637 0 1.570796" xyz="-0.0228853 -0.006 0.0074359"/>
    <parent link="fourth_wheel_link"/>
    <child link="r2_R_roller_link"/>
    <axis xyz="0 1 0"/>
  </joint>
  <link name="r2_R_roller_link">
    <visual>
      <geometry>
        <mesh filename="package://omni_robot_description/meshes/DAE/roller/roller.dae"/>
      </geometry>
    </visual>
    <collision>
      <geometry>
        <mesh filename="package://omni_robot_description/meshes/STL/roller/roller.stl"/>
      </geometry>
    </collision>
    <inertial>
      <origin xyz="0.0 0.0 0.0"/>
      <mass value="0.009"/>
      <inertia ixx="0.000001257" ixy="0" ixz="0" iyy="0.000000342" iyz="0" izz="0.000001257"/>
    </inertial>
    <surface>
      <friction>
        <ode>
          <mu1>1.2</mu1>
          <mu2>1.2</mu2>
          <kp>1e15</kp>
          <kd>1e13</kd>
        </ode>
      </friction>
      <bounce>
        <restitution_coefficient>0.01</restitution_coefficient>
        <threshold>0</threshold>
      </bounce>
      <contact>
        <ode>
          <max_vel>10</max_vel>
        </ode>
      </contact>
    </surface>
  </link>
  <joint name="r3_R_roller_joint" type="continuous">
    <origin rpy="-2.513274 0 1.570796" xyz="-0.0141439 -0.006 -0.0194674"/>
    <parent link="fourth_wheel_link"/>
    <child link="r3_R_roller_link"/>
    <axis xyz="0 1 0"/>
  </joint>
  <link name="r3_R_roller_link">
    <visual>
      <geometry>
        <mesh filename="package://omni_robot_description/meshes/DAE/roller/roller.dae"/>
      </geometry>
    </visual>
    <collision>
      <geometry>
        <mesh filename="package://omni_robot_description/meshes/STL/roller/roller.stl"/>
      </geometry>
    </collision>
    <inertial>
      <origin xyz="0.0 0.0 0.0"/>
      <mass value="0.009"/>
      <inertia ixx="0.000001257" ixy="0" ixz="0" iyy="0.000000342" iyz="0" izz="0.000001257"/>
    </inertial>
    <surface>
      <friction>
        <ode>
          <mu1>1.2</mu1>
          <mu2>1.2</mu2>
          <kp>1e15</kp>
          <kd>1e13</kd>
        </ode>
      </friction>
      <bounce>
        <restitution_coefficient>0.01</restitution_coefficient>
        <threshold>0</threshold>
      </bounce>
      <contact>
        <ode>
          <max_vel>10</max_vel>
        </ode>
      </contact>
    </surface>
  </link>
  <joint name="r4_R_roller_joint" type="continuous">
    <origin rpy="-3.769911 0 1.570796" xyz="0.0141439 -0.006 -0.0194674"/>
    <parent link="fourth_wheel_link"/>
    <child link="r4_R_roller_link"/>
    <axis xyz="0 1 0"/>
  </joint>
  <link name="r4_R_roller_link">
    <visual>
      <geometry>
        <mesh filename="package://omni_robot_description/meshes/DAE/roller/roller.dae"/>
      </geometry>
    </visual>
    <collision>
      <geometry>
        <mesh filename="package://omni_robot_description/meshes/STL/roller/roller.stl"/>
      </geometry>
    </collision>
    <inertial>
      <origin xyz="0.0 0.0 0.0"/>
      <mass value="0.009"/>
      <inertia ixx="0.000001257" ixy="0" ixz="0" iyy="0.000000342" iyz="0" izz="0.000001257"/>
    </inertial>
    <surface>
      <friction>
        <ode>
          <mu1>1.2</mu1>
          <mu2>1.2</mu2>
          <kp>1e15</kp>
          <kd>1e13</kd>
        </ode>
      </friction>
      <bounce>
        <restitution_coefficient>0.01</restitution_coefficient>
        <threshold>0</threshold>
      </bounce>
      <contact>
        <ode>
          <max_vel>10</max_vel>
        </ode>
      </contact>
    </surface>
  </link>
  <joint name="r5_R_roller_joint" type="continuous">
    <origin rpy="-5.026548 0 1.570796" xyz="0.0228853 -0.006 0.0074359"/>
    <parent link="fourth_wheel_link"/>
    <child link="r5_R_roller_link"/>
    <axis xyz="0 1 0"/>
  </joint>
  <link name="r5_R_roller_link">
    <visual>
      <geometry>
        <mesh filename="package://omni_robot_description/meshes/DAE/roller/roller.dae"/>
      </geometry>
    </visual>
    <collision>
      <geometry>
        <mesh filename="package://omni_robot_description/meshes/STL/roller/roller.stl"/>
      </geometry>
    </collision>
    <inertial>
      <origin xyz="0.0 0.0 0.0"/>
      <mass value="0.009"/>
      <inertia ixx="0.000001257" ixy="0" ixz="0" iyy="0.000000342" iyz="0" izz="0.000001257"/>
    </inertial>
    <surface>
      <friction>
        <ode>
          <mu1>1.2</mu1>
          <mu2>1.2</mu2>
          <kp>1e15</kp>
          <kd>1e13</kd>
        </ode>
      </friction>
      <bounce>
        <restitution_coefficient>0.01</restitution_coefficient>
        <threshold>0</threshold>
      </bounce>
      <contact>
        <ode>
          <max_vel>10</max_vel>
        </ode>
      </contact>
    </surface>
  </link>
  <joint name="r6_R_roller_joint" type="continuous">
    <origin rpy="0 0 1.570796" xyz="0 0.006 -0.024063"/>
    <parent link="fourth_wheel_link"/>
    <child link="r6_R_roller_link"/>
    <axis xyz="0 1 0"/>
  </joint>
  <link name="r6_R_roller_link">
    <visual>
      <geometry>
        <mesh filename="package://omni_robot_description/meshes/DAE/roller/roller.dae"/>
      </geometry>
    </visual>
    <collision>
      <geometry>
        <mesh filename="package://omni_robot_description/meshes/STL/roller/roller.stl"/>
      </geometry>
    </collision>
    <inertial>
      <origin xyz="0.0 0.0 0.0"/>
      <mass value="0.009"/>
      <inertia ixx="0.000001257" ixy="0" ixz="0" iyy="0.000000342" iyz="0" izz="0.000001257"/>
    </inertial>
    <surface>
      <friction>
        <ode>
          <mu1>1.2</mu1>
          <mu2>1.2</mu2>
          <kp>1e15</kp>
          <kd>1e13</kd>
        </ode>
      </friction>
      <bounce>
        <restitution_coefficient>0.01</restitution_coefficient>
        <threshold>0</threshold>
      </bounce>
      <contact>
        <ode>
          <max_vel>10</max_vel>
        </ode>
      </contact>
    </surface>
  </link>
  <joint name="r7_R_roller_joint" type="continuous">
    <origin rpy="-1.256637 0 1.570796" xyz="0.0228853 0.006 -0.0074359"/>
    <parent link="fourth_wheel_link"/>
    <child link="r7_R_roller_link"/>
    <axis xyz="0 1 0"/>
  </joint>
  <link name="r7_R_roller_link">
    <visual>
      <geometry>
        <mesh filename="package://omni_robot_description/meshes/DAE/roller/roller.dae"/>
      </geometry>
    </visual>
    <collision>
      <geometry>
        <mesh filename="package://omni_robot_description/meshes/STL/roller/roller.stl"/>
      </geometry>
    </collision>
    <inertial>
      <origin xyz="0.0 0.0 0.0"/>
      <mass value="0.009"/>
      <inertia ixx="0.000001257" ixy="0" ixz="0" iyy="0.000000342" iyz="0" izz="0.000001257"/>
    </inertial>
    <surface>
      <friction>
        <ode>
          <mu1>1.2</mu1>
          <mu2>1.2</mu2>
          <kp>1e15</kp>
          <kd>1e13</kd>
        </ode>
      </friction>
      <bounce>
        <restitution_coefficient>0.01</restitution_coefficient>
        <threshold>0</threshold>
      </bounce>
      <contact>
        <ode>
          <max_vel>10</max_vel>
        </ode>
      </contact>
    </surface>
  </link>
  <joint name="r8_R_roller_joint" type="continuous">
    <origin rpy="-2.513274 0 1.570796" xyz="0.0141439 0.006 0.0194674"/>
    <parent link="fourth_wheel_link"/>
    <child link="r8_R_roller_link"/>
    <axis xyz="0 1 0"/>
  </joint>
  <link name="r8_R_roller_link">
    <visual>
      <geometry>
        <mesh filename="package://omni_robot_description/meshes/DAE/roller/roller.dae"/>
      </geometry>
    </visual>
    <collision>
      <geometry>
        <mesh filename="package://omni_robot_description/meshes/STL/roller/roller.stl"/>
      </geometry>
    </collision>
    <inertial>
      <origin xyz="0.0 0.0 0.0"/>
      <mass value="0.009"/>
      <inertia ixx="0.000001257" ixy="0" ixz="0" iyy="0.000000342" iyz="0" izz="0.000001257"/>
    </inertial>
    <surface>
      <friction>
        <ode>
          <mu1>1.2</mu1>
          <mu2>1.2</mu2>
          <kp>1e15</kp>
          <kd>1e13</kd>
        </ode>
      </friction>
      <bounce>
        <restitution_coefficient>0.01</restitution_coefficient>
        <threshold>0</threshold>
      </bounce>
      <contact>
        <ode>
          <max_vel>10</max_vel>
        </ode>
      </contact>
    </surface>
  </link>
  <joint name="r9_R_roller_joint" type="continuous">
    <origin rpy="-3.769911 0 1.570796" xyz="-0.0141439 0.006 0.0194674"/>
    <parent link="fourth_wheel_link"/>
    <child link="r9_R_roller_link"/>
    <axis xyz="0 1 0"/>
  </joint>
  <link name="r9_R_roller_link">
    <visual>
      <geometry>
        <mesh filename="package://omni_robot_description/meshes/DAE/roller/roller.dae"/>
      </geometry>
    </visual>
    <collision>
      <geometry>
        <mesh filename="package://omni_robot_description/meshes/STL/roller/roller.stl"/>
      </geometry>
    </collision>
    <inertial>
      <origin xyz="0.0 0.0 0.0"/>
      <mass value="0.009"/>
      <inertia ixx="0.000001257" ixy="0" ixz="0" iyy="0.000000342" iyz="0" izz="0.000001257"/>
    </inertial>
    <surface>
      <friction>
        <ode>
          <mu1>1.2</mu1>
          <mu2>1.2</mu2>
          <kp>1e15</kp>
          <kd>1e13</kd>
        </ode>
      </friction>
      <bounce>
        <restitution_coefficient>0.01</restitution_coefficient>
        <threshold>0</threshold>
      </bounce>
      <contact>
        <ode>
          <max_vel>10</max_vel>
        </ode>
      </contact>
    </surface>
  </link>
  <joint name="r10_R_roller_joint" type="continuous">
    <origin rpy="-5.026548 0 1.570796" xyz="-0.0228853 0.006 -0.0074359"/>
    <parent link="fourth_wheel_link"/>
    <child link="r10_R_roller_link"/>
    <axis xyz="0 1 0"/>
  </joint>
  <link name="r10_R_roller_link">
    <visual>
      <geometry>
        <mesh filename="package://omni_robot_description/meshes/DAE/roller/roller.dae"/>
      </geometry>
    </visual>
    <collision>
      <geometry>
        <mesh filename="package://omni_robot_description/meshes/STL/roller/roller.stl"/>
      </geometry>
    </collision>
    <inertial>
      <origin xyz="0.0 0.0 0.0"/>
      <mass value="0.009"/>
      <inertia ixx="0.000001257" ixy="0" ixz="0" iyy="0.000000342" iyz="0" izz="0.000001257"/>
    </inertial>
    <surface>
      <friction>
        <ode>
          <mu1>1.2</mu1>
          <mu2>1.2</mu2>
          <kp>1e15</kp>
          <kd>1e13</kd>
        </ode>
      </friction>
      <bounce>
        <restitution_coefficient>0.01</restitution_coefficient>
        <threshold>0</threshold>
      </bounce>
      <contact>
        <ode>
          <max_vel>10</max_vel>
        </ode>
      </contact>
    </surface>
  </link>
  <joint name="front_lrf_joint" type="fixed">
    <origin xyz="0 0 0.1395"/>
    <parent link="base_link"/>
    <child link="front_lrf_link"/>
  </joint>
  <link name="front_lrf_link">
	</link>
  <transmission name="first_wheel_trans">
    <type>transmission_interface/SimpleTransmission</type>
    <joint name="first_wheel_joint">
      <hardwareInterface>hardware_interface/VelocityJointInterface</hardwareInterface>
    </joint>
    <actuator name="first_wheel_motor">
      <hardwareInterface>hardware_interface/VelocityJointInterface</hardwareInterface>
      <mechanicalReduction>30</mechanicalReduction>
    </actuator>
  </transmission>
  <transmission name="second_wheel_trans">
    <type>transmission_interface/SimpleTransmission</type>
    <joint name="second_wheel_joint">
      <hardwareInterface>hardware_interface/VelocityJointInterface</hardwareInterface>
    </joint>
    <actuator name="second_wheel_motor">
      <hardwareInterface>hardware_interface/VelocityJointInterface</hardwareInterface>
      <mechanicalReduction>30</mechanicalReduction>
    </actuator>
  </transmission>
  <transmission name="third_wheel_trans">
    <type>transmission_interface/SimpleTransmission</type>
    <joint name="third_wheel_joint">
      <hardwareInterface>hardware_interface/VelocityJointInterface</hardwareInterface>
    </joint>
    <actuator name="third_wheel_motor">
      <hardwareInterface>hardware_interface/VelocityJointInterface</hardwareInterface>
      <mechanicalReduction>30</mechanicalReduction>
    </actuator>
  </transmission>
  <transmission name="fourth_wheel_trans">
    <type>transmission_interface/SimpleTransmission</type>
    <joint name="fourth_wheel_joint">
      <hardwareInterface>hardware_interface/VelocityJointInterface</hardwareInterface>
    </joint>
    <actuator name="fourth_wheel_motor">
      <hardwareInterface>hardware_interface/VelocityJointInterface</hardwareInterface>
      <mechanicalReduction>30</mechanicalReduction>
    </actuator>
  </transmission>
  <!-- =============== Gazebo =============== -->
  <gazebo>
    <plugin filename="libgazebo_ros_control.so" name="gazebo_ros_control"/>
  </gazebo>
  <gazebo reference="base_link">
    <selfCollide>false</selfCollide>
    <mu1 value="0.05"/>
    <mu2 value="0.05"/>
  </gazebo>
  <gazebo reference="first_wheel_link">
    <selfCollide>false</selfCollide>
    <mu1 value="0.8"/>
    <mu2 value="0.8"/>
  </gazebo>
  <gazebo reference="second_wheel_link">
    <selfCollide>false</selfCollide>
    <mu1 value="0.8"/>
    <mu2 value="0.8"/>
  </gazebo>
  <gazebo reference="third_wheel_link">
    <selfCollide>false</selfCollide>
    <mu1 value="0.8"/>
    <mu2 value="0.8"/>
  </gazebo>
  <gazebo reference="fourth_wheel_link">
    <selfCollide>false</selfCollide>
    <mu1 value="0.8"/>
    <mu2 value="0.8"/>
  </gazebo>
  <gazebo reference="front_lrf_link">
    <sensor name="front_lrf_sensor" type="ray">
      <pose>0 0 0 0 0 0</pose>
      <visualize>true</visualize>
      <update_rate>40</update_rate>
      <ray>
        <scan>
          <horizontal>
            <samples>720</samples>
            <resolution>1</resolution>
            <min_angle>-3.14</min_angle>
            <max_angle>3.14</max_angle>
          </horizontal>
        </scan>
        <range>
          <min>0.1</min>
          <max>10</max>
          <resolution>0.01</resolution>
        </range>
        <noise>
          <type>gaussian</type>
          <mean>0.0</mean>
          <stddev>0.03</stddev>
        </noise>
      </ray>
      <plugin filename="libgazebo_ros_laser.so" name="gazebo_ros_front_lrf_controller">
        <topicName>front/scan</topicName>
        <!-- do ont set it to base_scan -->
        <frameName>front_lrf_link</frameName>
      </plugin>
    </sensor>
  </gazebo>
  <ros2_control name="GazeboSystem" type="system">
    <hardware>
      <plugin>gazebo_ros2_control/GazeboSystem</plugin>
    </hardware>
    
    <joint name="first_wheel_joint">
      <command_interface name="velocity">
        <param name="min">-3.14</param>
        <param name="max">3.14</param>
      </command_interface>
      <state_interface name="velocity"/>
    </joint>

    <joint name="second_wheel_joint">
      <command_interface name="velocity">
        <param name="min">-3.14</param>
        <param name="max">3.14</param>
      </command_interface>
      <state_interface name="velocity"/>
    </joint>

    <joint name="third_wheel_joint">
      <command_interface name="velocity">
        <param name="min">-3.14</param>
        <param name="max">3.14</param>
      </command_interface>
      <state_interface name="velocity"/>
    </joint>

    <joint name="fourth_wheel_joint">
      <command_interface name="velocity">
        <param name="min">-3.14</param>
        <param name="max">3.14</param>
      </command_interface>
      <state_interface name="velocity"/>
    </joint>
  </ros2_control>
</robot>
